{
  "version": 8,
  "blockIdVersion": 11,
  "anchorX": 0,
  "anchorY": 0,
  "anchorZ": 0,
  "blocks": [
    {
      "x": -21,
      "y": 10,
      "z": -5,
      "name": "Prototype_Rock_Concrete_Brick_Roof_Flat",
      "rotation": 1
    },
    {
      "x": -21,
      "y": 10,
      "z": -4,
      "name": "Prototype_Rock_Concrete_Brick_Roof_Flat",
      "rotation": 1
    },
    {
      "x": -20,
      "y": 10,
      "z": -4,
      "name": "Prototype_Rock_Concrete_Brick_Roof_Flat",
      "rotation": 1
    },
    {
      "x": -20,
      "y": 10,
      "z": -3,
      "name": "Prototype_Rock_Concrete_Brick_Roof_Flat",
      "rotation": 1
    },
    {
      "x": -19,
      "y": 10,
      "z": -4,
      "name": "Prototype_Rock_Concrete_Brick_Roof_Flat",
      "rotation": 1
    },
    {
      "x": -19,
      "y": 10,
      "z": -3,
      "name": "Prototype_Rock_Concrete_Brick_Roof_Flat",
      "rotation": 1
    },
    {
      "x": -19,
      "y": 3,
      "z": 0,
      "name": "Rock_Slate_Cobble_Beam",
      "rotation": 5
    },
    {
      "x": -18,
      "y": 10,
      "z": -4,
      "name": "Prototype_Rock_Concrete_Brick_Roof_Flat",
      "rotation": 1
    },
    {
      "x": -18,
      "y": 10,
      "z": -3,
      "name": "Prototype_Rock_Concrete_Brick_Roof_Flat",
      "rotation": 1
    },
    {
      "x": -18,
      "y": 3,
      "z": 0,
      "name": "Rock_Slate_Brick_Pillar_Middle",
      "rotation": 7
    },
    {
      "x": -17,
      "y": 10,
      "z": -3,
      "name": "Prototype_Rock_Concrete_Brick_Roof_Flat",
      "rotation": 1
    },
    {
      "x": -17,
      "y": 10,
      "z": -2,
      "name": "Prototype_Rock_Concrete_Brick_Roof_Flat",
      "rotation": 1
    },
    {
      "x": -17,
      "y": 3,
      "z": 0,
      "name": "Rock_Slate_Brick_Pillar_Middle",
      "rotation": 7
    },
    {
      "x": -16,
      "y": 10,
      "z": -3,
      "name": "Prototype_Rock_Concrete_Brick_Roof_Flat",
      "rotation": 1
    },
    {
      "x": -16,
      "y": 10,
      "z": -2,
      "name": "Prototype_Rock_Concrete_Brick_Roof_Flat",
      "rotation": 1
    },
    {
      "x": -16,
      "y": 3,
      "z": 0,
      "name": "Rock_Slate_Brick_Pillar_Middle",
      "rotation": 7
    },
    {
      "x": -16,
      "y": 3,
      "z": 3,
      "name": "Rock_Slate_Brick_Smooth_Half",
      "rotation": 7
    },
    {
      "x": -16,
      "y": 3,
      "z": 4,
      "name": "Rock_Slate_Brick_Smooth_Half",
      "rotation": 7
    },
    {
      "x": -15,
      "y": 10,
      "z": -3,
      "name": "Prototype_Rock_Concrete_Brick_Roof_Flat",
      "rotation": 1
    },
    {
      "x": -15,
      "y": 10,
      "z": -2,
      "name": "Prototype_Rock_Concrete_Brick_Roof_Flat",
      "rotation": 1
    },
    {
      "x": -15,
      "y": 10,
      "z": -1,
      "name": "Prototype_Rock_Concrete_Brick_Roof_Flat",
      "rotation": 1
    },
    {
      "x": -15,
      "y": 3,
      "z": 0,
      "name": "Rock_Slate_Brick_Pillar_Middle",
      "rotation": 7
    },
    {
      "x": -15,
      "y": 3,
      "z": 2,
      "name": "*Build_Black_Roof_State_Definitions_Corner_Left",
      "rotation": 35
    },
    {
      "x": -15,
      "y": 4,
      "z": 2,
      "name": "*Build_Black_Roof_State_Definitions_Corner_Left",
      "rotation": 2
    },
    {
      "x": -15,
      "y": 2,
      "z": 3,
      "name": "Build_Black_Roof",
      "rotation": 35
    },
    {
      "x": -15,
      "y": 3,
      "z": 3,
      "name": "Rock_Slate"
    },
    {
      "x": -15,
      "y": 4,
      "z": 3,
      "name": "Build_Black_Roof",
      "rotation": 3
    },
    {
      "x": -15,
      "y": 2,
      "z": 4,
      "name": "Build_Black_Roof",
      "rotation": 35
    },
    {
      "x": -15,
      "y": 3,
      "z": 4,
      "name": "Rock_Slate"
    },
    {
      "x": -15,
      "y": 4,
      "z": 4,
      "name": "Build_Black_Roof",
      "rotation": 3
    },
    {
      "x": -15,
      "y": 3,
      "z": 5,
      "name": "*Build_Black_Roof_State_Definitions_Corner_Right",
      "rotation": 35
    },
    {
      "x": -15,
      "y": 4,
      "z": 5,
      "name": "*Build_Black_Roof_State_Definitions_Corner_Right"
    },
    {
      "x": -15,
      "y": 10,
      "z": 15,
      "name": "Prototype_Rock_Concrete_Brick_Roof_Flat",
      "rotation": 3
    },
    {
      "x": -15,
      "y": 10,
      "z": 16,
      "name": "Prototype_Rock_Concrete_Brick_Roof_Flat",
      "rotation": 1
    },
    {
      "x": -14,
      "y": 10,
      "z": -2,
      "name": "Prototype_Rock_Concrete_Brick_Roof_Flat",
      "rotation": 1
    },
    {
      "x": -14,
      "y": 10,
      "z": -1,
      "name": "Prototype_Rock_Concrete_Brick_Roof_Flat",
      "rotation": 1
    },
    {
      "x": -14,
      "y": 3,
      "z": 0,
      "name": "Rock_Slate_Brick_Pillar_Middle",
      "rotation": 7
    },
    {
      "x": -14,
      "y": 3,
      "z": 2,
      "name": "Build_Black_Roof",
      "rotation": 34
    },
    {
      "x": -14,
      "y": 4,
      "z": 2,
      "name": "*Build_Black_Roof_State_Definitions_Inverted_Corner_Right",
      "rotation": 3
    },
    {
      "x": -14,
      "y": 2,
      "z": 3,
      "name": "Rock_Slate",
      "rotation": 2
    },
    {
      "x": -14,
      "y": 3,
      "z": 3,
      "name": "Rock_Slate",
      "rotation": 2
    },
    {
      "x": -14,
      "y": 4,
      "z": 3,
      "name": "Rock_Slate",
      "rotation": 2
    },
    {
      "x": -14,
      "y": 2,
      "z": 4,
      "name": "Rock_Slate"
    },
    {
      "x": -14,
      "y": 3,
      "z": 4,
      "name": "Rock_Slate",
      "rotation": 2
    },
    {
      "x": -14,
      "y": 4,
      "z": 4,
      "name": "Rock_Slate",
      "rotation": 2
    },
    {
      "x": -14,
      "y": 3,
      "z": 5,
      "name": "Build_Black_Roof",
      "rotation": 32
    },
    {
      "x": -14,
      "y": 4,
      "z": 5,
      "name": "*Build_Black_Roof_State_Definitions_Inverted_Corner_Left",
      "rotation": 3
    },
    {
      "x": -14,
      "y": 10,
      "z": 14,
      "name": "Prototype_Rock_Concrete_Brick_Roof_Flat",
      "rotation": 3
    },
    {
      "x": -14,
      "y": 10,
      "z": 15,
      "name": "Prototype_Rock_Concrete_Brick_Roof_Flat",
      "rotation": 1
    },
    {
      "x": -14,
      "y": 10,
      "z": 16,
      "name": "Prototype_Rock_Concrete_Brick_Roof_Flat",
      "rotation": 1
    },
    {
      "x": -13,
      "y": 10,
      "z": -2,
      "name": "Prototype_Rock_Concrete_Brick_Roof_Flat",
      "rotation": 1
    },
    {
      "x": -13,
      "y": 10,
      "z": -1,
      "name": "Prototype_Rock_Concrete_Brick_Roof_Flat",
      "rotation": 1
    },
    {
      "x": -13,
      "y": 3,
      "z": 0,
      "name": "Rock_Slate_Brick_Pillar_Middle",
      "rotation": 7
    },
    {
      "x": -13,
      "y": 4,
      "z": 0,
      "name": "Rock_Slate_Brick_Roof_Flat",
      "rotation": 2
    },
    {
      "x": -13,
      "y": 2,
      "z": 1,
      "name": "*Build_Black_Roof_State_Definitions_Corner_Right",
      "rotation": 34
    },
    {
      "x": -13,
      "y": 3,
      "z": 1,
      "name": "Rock_Slate_Brick_Smooth"
    },
    {
      "x": -13,
      "y": 4,
      "z": 1,
      "name": "Build_Black_Roof",
      "rotation": 2
    },
    {
      "x": -13,
      "y": 2,
      "z": 2,
      "name": "Build_Black_Roof",
      "rotation": 35
    },
    {
      "x": -13,
      "y": 3,
      "z": 2,
      "name": "Rock_Slate_Brick_Smooth"
    },
    {
      "x": -13,
      "y": 4,
      "z": 2,
      "name": "Rock_Slate_Brick_Smooth"
    },
    {
      "x": -13,
      "y": 5,
      "z": 2,
      "name": "Transparent_Glass"
    },
    {
      "x": -13,
      "y": 6,
      "z": 2,
      "name": "*Build_Black_Roof_State_Definitions_Corner_Left",
      "rotation": 2
    },
    {
      "x": -13,
      "y": 2,
      "z": 3,
      "name": "Rock_Slate",
      "rotation": 2
    },
    {
      "x": -13,
      "y": 3,
      "z": 3,
      "name": "Rock_Slate_Brick_Smooth"
    },
    {
      "x": -13,
      "y": 4,
      "z": 3,
      "name": "Build_Black_Roof",
      "rotation": 33
    },
    {
      "x": -13,
      "y": 5,
      "z": 3,
      "name": "Transparent_Glass"
    },
    {
      "x": -13,
      "y": 6,
      "z": 3,
      "name": "Build_Black_Roof",
      "rotation": 3
    },
    {
      "x": -13,
      "y": 2,
      "z": 4,
      "name": "Rock_Slate",
      "rotation": 2
    },
    {
      "x": -13,
      "y": 3,
      "z": 4,
      "name": "Rock_Slate_Brick_Smooth"
    },
    {
      "x": -13,
      "y": 4,
      "z": 4,
      "name": "Build_Black_Roof",
      "rotation": 33
    },
    {
      "x": -13,
      "y": 5,
      "z": 4,
      "name": "Transparent_Glass"
    },
    {
      "x": -13,
      "y": 6,
      "z": 4,
      "name": "Build_Black_Roof",
      "rotation": 3
    },
    {
      "x": -13,
      "y": 2,
      "z": 5,
      "name": "Build_Black_Roof",
      "rotation": 35
    },
    {
      "x": -13,
      "y": 3,
      "z": 5,
      "name": "Rock_Slate_Brick_Smooth"
    },
    {
      "x": -13,
      "y": 4,
      "z": 5,
      "name": "Rock_Slate",
      "rotation": 2
    },
    {
      "x": -13,
      "y": 5,
      "z": 5,
      "name": "Transparent_Glass"
    },
    {
      "x": -13,
      "y": 6,
      "z": 5,
      "name": "*Build_Black_Roof_State_Definitions_Corner_Right"
    },
    {
      "x": -13,
      "y": 2,
      "z": 6,
      "name": "*Build_Black_Roof_State_Definitions_Corner_Left",
      "rotation": 32
    },
    {
      "x": -13,
      "y": 3,
      "z": 6,
      "name": "Rock_Slate_Brick_Smooth"
    },
    {
      "x": -13,
      "y": 4,
      "z": 6,
      "name": "Build_Black_Roof"
    },
    {
      "x": -13,
      "y": 10,
      "z": 12,
      "name": "Prototype_Rock_Concrete_Brick_Roof_Flat",
      "rotation": 1
    },
    {
      "x": -13,
      "y": 10,
      "z": 13,
      "name": "Prototype_Rock_Concrete_Brick_Roof_Flat",
      "rotation": 3
    },
    {
      "x": -13,
      "y": 10,
      "z": 14,
      "name": "Prototype_Rock_Concrete_Brick_Roof_Flat",
      "rotation": 1
    },
    {
      "x": -13,
      "y": 10,
      "z": 15,
      "name": "Prototype_Rock_Concrete_Brick_Roof_Flat",
      "rotation": 1
    },
    {
      "x": -12,
      "y": 10,
      "z": -2,
      "name": "Prototype_Rock_Concrete_Brick_Roof_Flat",
      "rotation": 1
    },
    {
      "x": -12,
      "y": 10,
      "z": -1,
      "name": "Prototype_Rock_Concrete_Brick_Roof_Flat",
      "rotation": 1
    },
    {
      "x": -12,
      "y": 2,
      "z": 0,
      "name": "Build_Black_Roof_Shallow",
      "rotation": 35
    },
    {
      "x": -12,
      "y": 3,
      "z": 0,
      "name": "Rock_Slate_Brick_Smooth"
    },
    {
      "x": -12,
      "y": 4,
      "z": 0,
      "name": "Build_Black_Roof",
      "rotation": 3
    },
    {
      "x": -12,
      "y": 10,
      "z": 0,
      "name": "Prototype_Rock_Concrete_Brick_Roof_Flat",
      "rotation": 1
    },
    {
      "x": -12,
      "y": 2,
      "z": 1,
      "name": "*Build_Black_Roof_State_Definitions_Inverted_Corner_Left",
      "rotation": 35
    },
    {
      "x": -12,
      "y": 3,
      "z": 1,
      "name": "Rock_Slate",
      "rotation": 2
    },
    {
      "x": -12,
      "y": 4,
      "z": 1,
      "name": "Rock_Slate_Brick_Smooth"
    },
    {
      "x": -12,
      "y": 5,
      "z": 1,
      "name": "Transparent_Glass"
    },
    {
      "x": -12,
      "y": 6,
      "z": 1,
      "name": "Rock_Slate_Brick_Smooth_Half"
    },
    {
      "x": -12,
      "y": 2,
      "z": 2,
      "name": "Rock_Slate",
      "rotation": 2
    },
    {
      "x": -12,
      "y": 3,
      "z": 2,
      "name": "Rock_Slate",
      "rotation": 2
    },
    {
      "x": -12,
      "y": 4,
      "z": 2,
      "name": "Deco_Lever",
      "rotation": 1
    },
    {
      "x": -12,
      "y": 6,
      "z": 2,
      "name": "Rock_Slate"
    },
    {
      "x": -12,
      "y": 2,
      "z": 3,
      "name": "Rock_Slate",
      "rotation": 2
    },
    {
      "x": -12,
      "y": 3,
      "z": 3,
      "name": "Rock_Slate_Brick_Smooth"
    },
    {
      "x": -12,
      "y": 4,
      "z": 3,
      "name": "Furniture_Temple_Dark_Stool",
      "rotation": 1
    },
    {
      "x": -12,
      "y": 5,
      "z": 3,
      "name": "Build_Lightsource_Blue"
    },
    {
      "x": -12,
      "y": 6,
      "z": 3,
      "name": "Rock_Slate",
      "rotation": 2
    },
    {
      "x": -12,
      "y": 7,
      "z": 3,
      "name": "Rock_Slate_Brick_Roof_Flat",
      "rotation": 3
    },
    {
      "x": -12,
      "y": 2,
      "z": 4,
      "name": "Rock_Slate",
      "rotation": 2
    },
    {
      "x": -12,
      "y": 3,
      "z": 4,
      "name": "Rock_Slate_Brick_Smooth"
    },
    {
      "x": -12,
      "y": 4,
      "z": 4,
      "name": "Furniture_Human_Ruins_Desk",
      "rotation": 2
    },
    {
      "x": -12,
      "y": 5,
      "z": 4,
      "name": "Furniture_Scarak_Hive_Lantern"
    },
    {
      "x": -12,
      "y": 6,
      "z": 4,
      "name": "Rock_Slate",
      "rotation": 2
    },
    {
      "x": -12,
      "y": 7,
      "z": 4,
      "name": "Rock_Slate_Brick_Roof_Flat",
      "rotation": 3
    },
    {
      "x": -12,
      "y": 2,
      "z": 5,
      "name": "Rock_Slate",
      "rotation": 2
    },
    {
      "x": -12,
      "y": 3,
      "z": 5,
      "name": "Rock_Slate",
      "rotation": 2
    },
    {
      "x": -12,
      "y": 4,
      "z": 5,
      "name": "Deco_Lever",
      "rotation": 1
    },
    {
      "x": -12,
      "y": 6,
      "z": 5,
      "name": "Rock_Slate",
      "rotation": 2
    },
    {
      "x": -12,
      "y": 2,
      "z": 6,
      "name": "Build_Black_Roof",
      "rotation": 32
    },
    {
      "x": -12,
      "y": 3,
      "z": 6,
      "name": "Rock_Slate",
      "rotation": 2
    },
    {
      "x": -12,
      "y": 4,
      "z": 6,
      "name": "Rock_Slate_Brick_Smooth"
    },
    {
      "x": -12,
      "y": 5,
      "z": 6,
      "name": "Transparent_Glass"
    },
    {
      "x": -12,
      "y": 6,
      "z": 6,
      "name": "Rock_Slate_Brick_Smooth_Half"
    },
    {
      "x": -12,
      "y": 3,
      "z": 7,
      "name": "Rock_Slate_Brick_Half",
      "rotation": 4
    },
    {
      "x": -12,
      "y": 10,
      "z": 11,
      "name": "Prototype_Rock_Concrete_Brick_Roof_Flat",
      "rotation": 1
    },
    {
      "x": -12,
      "y": 10,
      "z": 12,
      "name": "Prototype_Rock_Concrete_Brick_Roof_Flat",
      "rotation": 1
    },
    {
      "x": -12,
      "y": 10,
      "z": 13,
      "name": "Prototype_Rock_Concrete_Brick_Roof_Flat",
      "rotation": 1
    },
    {
      "x": -12,
      "y": 10,
      "z": 14,
      "name": "Prototype_Rock_Concrete_Brick_Roof_Flat",
      "rotation": 1
    },
    {
      "x": -11,
      "y": 10,
      "z": -1,
      "name": "Prototype_Rock_Concrete_Brick_Roof_Flat",
      "rotation": 1
    },
    {
      "x": -11,
      "y": 2,
      "z": 0,
      "name": "Build_Black_Roof_Shallow",
      "filler": 1,
      "rotation": 35
    },
    {
      "x": -11,
      "y": 3,
      "z": 0,
      "name": "Rock_Slate_Brick_Smooth"
    },
    {
      "x": -11,
      "y": 4,
      "z": 0,
      "name": "Rock_Slate",
      "rotation": 2
    },
    {
      "x": -11,
      "y": 5,
      "z": 0,
      "name": "Build_Black_Roof_Steep",
      "rotation": 3
    },
    {
      "x": -11,
      "y": 6,
      "z": 0,
      "name": "Build_Black_Roof_Steep",
      "filler": 1024,
      "rotation": 3
    },
    {
      "x": -11,
      "y": 10,
      "z": 0,
      "name": "Prototype_Rock_Concrete_Brick_Roof_Flat",
      "rotation": 1
    },
    {
      "x": -11,
      "y": 2,
      "z": 1,
      "name": "Rock_Slate",
      "rotation": 2
    },
    {
      "x": -11,
      "y": 3,
      "z": 1,
      "name": "Rock_Slate",
      "rotation": 2
    },
    {
      "x": -11,
      "y": 4,
      "z": 1,
      "name": "Rock_Slate",
      "rotation": 2
    },
    {
      "x": -11,
      "y": 5,
      "z": 1,
      "name": "Rock_Slate"
    },
    {
      "x": -11,
      "y": 6,
      "z": 1,
      "name": "Rock_Slate",
      "rotation": 2
    },
    {
      "x": -11,
      "y": 2,
      "z": 2,
      "name": "Rock_Slate",
      "rotation": 2
    },
    {
      "x": -11,
      "y": 3,
      "z": 2,
      "name": "Rock_Slate",
      "rotation": 2
    },
    {
      "x": -11,
      "y": 4,
      "z": 2,
      "name": "Furniture_Human_Ruins_Chair",
      "rotation": 3
    },
    {
      "x": -11,
      "y": 5,
      "z": 2,
      "name": "Furniture_Human_Ruins_Chair",
      "filler": 1024,
      "rotation": 3
    },
    {
      "x": -11,
      "y": 6,
      "z": 2,
      "name": "Rock_Slate"
    },
    {
      "x": -11,
      "y": 7,
      "z": 2,
      "name": "Rock_Slate_Brick_Half"
    },
    {
      "x": -11,
      "y": 2,
      "z": 3,
      "name": "Rock_Slate",
      "rotation": 2
    },
    {
      "x": -11,
      "y": 3,
      "z": 3,
      "name": "Rock_Slate_Brick_Smooth"
    },
    {
      "x": -11,
      "y": 4,
      "z": 3,
      "name": "Furniture_Temple_Dark_Stool",
      "rotation": 1
    },
    {
      "x": -11,
      "y": 5,
      "z": 3,
      "name": "Barrier"
    },
    {
      "x": -11,
      "y": 6,
      "z": 3,
      "name": "Rock_Slate",
      "rotation": 2
    },
    {
      "x": -11,
      "y": 7,
      "z": 3,
      "name": "Build_Black_Roof",
      "rotation": 3
    },
    {
      "x": -11,
      "y": 2,
      "z": 4,
      "name": "Rock_Slate",
      "rotation": 2
    },
    {
      "x": -11,
      "y": 3,
      "z": 4,
      "name": "Rock_Slate_Brick_Smooth"
    },
    {
      "x": -11,
      "y": 4,
      "z": 4,
      "name": "Furniture_Human_Ruins_Desk",
      "filler": 1,
      "rotation": 2
    },
    {
      "x": -11,
      "y": 5,
      "z": 4,
      "name": "Barrier"
    },
    {
      "x": -11,
      "y": 6,
      "z": 4,
      "name": "Rock_Slate",
      "rotation": 2
    },
    {
      "x": -11,
      "y": 7,
      "z": 4,
      "name": "Build_Black_Roof",
      "rotation": 3
    },
    {
      "x": -11,
      "y": 2,
      "z": 5,
      "name": "Rock_Slate",
      "rotation": 2
    },
    {
      "x": -11,
      "y": 3,
      "z": 5,
      "name": "Rock_Slate",
      "rotation": 2
    },
    {
      "x": -11,
      "y": 4,
      "z": 5,
      "name": "Furniture_Human_Ruins_Chair",
      "rotation": 3
    },
    {
      "x": -11,
      "y": 5,
      "z": 5,
      "name": "Furniture_Human_Ruins_Chair",
      "filler": 1024,
      "rotation": 3
    },
    {
      "x": -11,
      "y": 6,
      "z": 5,
      "name": "Rock_Slate",
      "rotation": 2
    },
    {
      "x": -11,
      "y": 7,
      "z": 5,
      "name": "Rock_Slate_Brick_Half"
    },
    {
      "x": -11,
      "y": 2,
      "z": 6,
      "name": "Rock_Slate",
      "rotation": 2
    },
    {
      "x": -11,
      "y": 3,
      "z": 6,
      "name": "Rock_Slate",
      "rotation": 2
    },
    {
      "x": -11,
      "y": 4,
      "z": 6,
      "name": "Rock_Slate"
    },
    {
      "x": -11,
      "y": 5,
      "z": 6,
      "name": "Rock_Slate"
    },
    {
      "x": -11,
      "y": 6,
      "z": 6,
      "name": "Rock_Slate",
      "rotation": 2
    },
    {
      "x": -11,
      "y": 2,
      "z": 7,
      "name": "Rock_Slate_Brick_Half",
      "rotation": 4
    },
    {
      "x": -11,
      "y": 3,
      "z": 7,
      "name": "Rock_Slate",
      "rotation": 2
    },
    {
      "x": -11,
      "y": 4,
      "z": 7,
      "name": "Rock_Slate_Brick_Smooth"
    },
    {
      "x": -11,
      "y": 5,
      "z": 7,
      "name": "Build_Black_Roof_Steep",
      "rotation": 3
    },
    {
      "x": -11,
      "y": 6,
      "z": 7,
      "name": "Build_Black_Roof_Steep",
      "filler": 1024,
      "rotation": 3
    },
    {
      "x": -11,
      "y": 10,
      "z": 10,
      "name": "Prototype_Rock_Concrete_Brick_Roof_Flat"
    },
    {
      "x": -11,
      "y": 10,
      "z": 11,
      "name": "Prototype_Rock_Concrete_Brick_Roof_Flat",
      "rotation": 1
    },
    {
      "x": -11,
      "y": 10,
      "z": 12,
      "name": "Prototype_Rock_Concrete_Brick_Roof_Flat",
      "rotation": 1
    },
    {
      "x": -10,
      "y": 10,
      "z": -1,
      "name": "Prototype_Rock_Concrete_Brick_Roof_Flat",
      "rotation": 1
    },
    {
      "x": -10,
      "y": 1,
      "z": 0,
      "name": "Rock_Slate_Brick_Half",
      "rotation": 6
    },
    {
      "x": -10,
      "y": 2,
      "z": 0,
      "name": "Rock_Slate",
      "rotation": 2
    },
    {
      "x": -10,
      "y": 3,
      "z": 0,
      "name": "Rock_Slate_Brick_Smooth"
    },
    {
      "x": -10,
      "y": 4,
      "z": 0,
      "name": "Rock_Slate",
      "rotation": 2
    },
    {
      "x": -10,
      "y": 5,
      "z": 0,
      "name": "Rock_Slate",
      "rotation": 2
    },
    {
      "x": -10,
      "y": 6,
      "z": 0,
      "name": "Rock_Slate",
      "rotation": 2
    },
    {
      "x": -10,
      "y": 7,
      "z": 0,
      "name": "Rock_Slate_Brick_Roof_Flat",
      "rotation": 2
    },
    {
      "x": -10,
      "y": 10,
      "z": 0,
      "name": "Prototype_Rock_Concrete_Brick_Roof_Flat",
      "rotation": 1
    },
    {
      "x": -10,
      "y": 1,
      "z": 1,
      "name": "Rock_Slate_Brick_Pillar_Base",
      "rotation": 34
    },
    {
      "x": -10,
      "y": 2,
      "z": 1,
      "name": "Rock_Slate",
      "rotation": 2
    },
    {
      "x": -10,
      "y": 3,
      "z": 1,
      "name": "Rock_Slate",
      "rotation": 2
    },
    {
      "x": -10,
      "y": 4,
      "z": 1,
      "name": "Build_Black_Roof_Steep",
      "filler": 31744,
      "rotation": 32
    },
    {
      "x": -10,
      "y": 5,
      "z": 1,
      "name": "Build_Black_Roof_Steep",
      "rotation": 32
    },
    {
      "x": -10,
      "y": 6,
      "z": 1,
      "name": "Rock_Slate",
      "rotation": 2
    },
    {
      "x": -10,
      "y": 2,
      "z": 2,
      "name": "Rock_Slate",
      "rotation": 2
    },
    {
      "x": -10,
      "y": 3,
      "z": 2,
      "name": "Rock_Slate",
      "rotation": 2
    },
    {
      "x": -10,
      "y": 5,
      "z": 2,
      "name": "Barrier"
    },
    {
      "x": -10,
      "y": 6,
      "z": 2,
      "name": "Rock_Slate",
      "rotation": 2
    },
    {
      "x": -10,
      "y": 7,
      "z": 2,
      "name": "Rock_Slate_Brick_Smooth_Half"
    },
    {
      "x": -10,
      "y": 2,
      "z": 3,
      "name": "Rock_Slate",
      "rotation": 2
    },
    {
      "x": -10,
      "y": 3,
      "z": 3,
      "name": "Rock_Slate_Brick_Smooth"
    },
    {
      "x": -10,
      "y": 6,
      "z": 3,
      "name": "Rock_Slate",
      "rotation": 2
    },
    {
      "x": -10,
      "y": 7,
      "z": 3,
      "name": "Rock_Slate",
      "rotation": 2
    },
    {
      "x": -10,
      "y": 8,
      "z": 3,
      "name": "Build_Black_Roof",
      "rotation": 3
    },
    {
      "x": -10,
      "y": 2,
      "z": 4,
      "name": "Rock_Slate",
      "rotation": 2
    },
    {
      "x": -10,
      "y": 3,
      "z": 4,
      "name": "Rock_Slate_Brick_Smooth"
    },
    {
      "x": -10,
      "y": 6,
      "z": 4,
      "name": "Rock_Slate",
      "rotation": 2
    },
    {
      "x": -10,
      "y": 7,
      "z": 4,
      "name": "Rock_Slate",
      "rotation": 2
    },
    {
      "x": -10,
      "y": 8,
      "z": 4,
      "name": "Build_Black_Roof",
      "rotation": 3
    },
    {
      "x": -10,
      "y": 2,
      "z": 5,
      "name": "Rock_Slate",
      "rotation": 2
    },
    {
      "x": -10,
      "y": 3,
      "z": 5,
      "name": "Rock_Slate",
      "rotation": 2
    },
    {
      "x": -10,
      "y": 5,
      "z": 5,
      "name": "Barrier"
    },
    {
      "x": -10,
      "y": 6,
      "z": 5,
      "name": "Rock_Slate",
      "rotation": 2
    },
    {
      "x": -10,
      "y": 7,
      "z": 5,
      "name": "Rock_Slate_Brick_Smooth_Half"
    },
    {
      "x": -10,
      "y": 1,
      "z": 6,
      "name": "Rock_Slate_Brick_Pillar_Base",
      "rotation": 34
    },
    {
      "x": -10,
      "y": 2,
      "z": 6,
      "name": "Rock_Slate",
      "rotation": 2
    },
    {
      "x": -10,
      "y": 3,
      "z": 6,
      "name": "Rock_Slate",
      "rotation": 2
    },
    {
      "x": -10,
      "y": 4,
      "z": 6,
      "name": "Build_Black_Roof_Steep",
      "filler": 31744,
      "rotation": 34
    },
    {
      "x": -10,
      "y": 5,
      "z": 6,
      "name": "Build_Black_Roof_Steep",
      "rotation": 34
    },
    {
      "x": -10,
      "y": 6,
      "z": 6,
      "name": "Rock_Slate",
      "rotation": 2
    },
    {
      "x": -10,
      "y": 1,
      "z": 7,
      "name": "Rock_Slate_Brick_Half",
      "rotation": 4
    },
    {
      "x": -10,
      "y": 2,
      "z": 7,
      "name": "Rock_Slate",
      "rotation": 2
    },
    {
      "x": -10,
      "y": 3,
      "z": 7,
      "name": "Rock_Slate",
      "rotation": 2
    },
    {
      "x": -10,
      "y": 4,
      "z": 7,
      "name": "Rock_Slate",
      "rotation": 2
    },
    {
      "x": -10,
      "y": 5,
      "z": 7,
      "name": "Rock_Slate",
      "rotation": 2
    },
    {
      "x": -10,
      "y": 6,
      "z": 7,
      "name": "Rock_Slate",
      "rotation": 2
    },
    {
      "x": -10,
      "y": 7,
      "z": 7,
      "name": "Rock_Slate_Brick_Roof_Flat",
      "rotation": 3
    },
    {
      "x": -10,
      "y": 10,
      "z": 8,
      "name": "Prototype_Rock_Concrete_Brick_Roof_Flat",
      "rotation": 1
    },
    {
      "x": -10,
      "y": 10,
      "z": 9,
      "name": "Prototype_Rock_Concrete_Brick_Roof_Flat"
    },
    {
      "x": -10,
      "y": 10,
      "z": 10,
      "name": "Prototype_Rock_Concrete_Brick_Roof_Flat"
    },
    {
      "x": -10,
      "y": 10,
      "z": 11,
      "name": "Prototype_Rock_Concrete_Brick_Roof_Flat"
    },
    {
      "x": -9,
      "y": 1,
      "z": 0,
      "name": "Rock_Slate_Brick_Smooth_Half",
      "rotation": 6
    },
    {
      "x": -9,
      "y": 2,
      "z": 0,
      "name": "Rock_Slate",
      "rotation": 2
    },
    {
      "x": -9,
      "y": 3,
      "z": 0,
      "name": "Rock_Slate",
      "rotation": 2
    },
    {
      "x": -9,
      "y": 4,
      "z": 0,
      "name": "Rock_Slate_Brick_Smooth"
    },
    {
      "x": -9,
      "y": 5,
      "z": 0,
      "name": "*Furniture_Temple_Dark_Trapdoor_State_Definitions_CloseDoorOut"
    },
    {
      "x": -9,
      "y": 6,
      "z": 0,
      "name": "Rock_Slate",
      "rotation": 2
    },
    {
      "x": -9,
      "y": 7,
      "z": 0,
      "name": "Build_Black_Roof",
      "rotation": 2
    },
    {
      "x": -9,
      "y": 10,
      "z": 0,
      "name": "Prototype_Rock_Concrete_Brick_Roof_Flat",
      "rotation": 1
    },
    {
      "x": -9,
      "y": 0,
      "z": 1,
      "name": "Furniture_Human_Ruins_Table",
      "filler": 31775,
      "rotation": 6
    },
    {
      "x": -9,
      "y": 1,
      "z": 1,
      "name": "Furniture_Human_Ruins_Table",
      "filler": 31,
      "rotation": 6
    },
    {
      "x": -9,
      "y": 2,
      "z": 1,
      "name": "Rock_Slate",
      "rotation": 2
    },
    {
      "x": -9,
      "y": 3,
      "z": 1,
      "name": "Rock_Slate",
      "rotation": 2
    },
    {
      "x": -9,
      "y": 6,
      "z": 1,
      "name": "Rock_Slate_Brick_Smooth_Half",
      "rotation": 8
    },
    {
      "x": -9,
      "y": 8,
      "z": 1,
      "name": "Rock_Slate_Brick_Smooth_Half"
    },
    {
      "x": -9,
      "y": 10,
      "z": 1,
      "name": "Prototype_Rock_Concrete_Brick_Roof_Flat",
      "rotation": 1
    },
    {
      "x": -9,
      "y": 1,
      "z": 2,
      "name": "Rock_Slate_Brick_Wall",
      "rotation": 2
    },
    {
      "x": -9,
      "y": 2,
      "z": 2,
      "name": "Rock_Slate",
      "rotation": 2
    },
    {
      "x": -9,
      "y": 3,
      "z": 2,
      "name": "Rock_Slate_Brick_Smooth"
    },
    {
      "x": -9,
      "y": 4,
      "z": 2,
      "name": "Furniture_Jungle_Chair",
      "rotation": 2
    },
    {
      "x": -9,
      "y": 5,
      "z": 2,
      "name": "Furniture_Jungle_Chair",
      "filler": 1024,
      "rotation": 2
    },
    {
      "x": -9,
      "y": 7,
      "z": 2,
      "name": "Rock_Slate",
      "rotation": 2
    },
    {
      "x": -9,
      "y": 8,
      "z": 2,
      "name": "Rock_Slate_Brick_Half"
    },
    {
      "x": -9,
      "y": 2,
      "z": 3,
      "name": "Rock_Slate",
      "rotation": 2
    },
    {
      "x": -9,
      "y": 3,
      "z": 3,
      "name": "Rock_Slate_Brick_Smooth"
    },
    {
      "x": -9,
      "y": 6,
      "z": 3,
      "name": "Rock_Slate",
      "rotation": 2
    },
    {
      "x": -9,
      "y": 7,
      "z": 3,
      "name": "Rock_Slate",
      "rotation": 2
    },
    {
      "x": -9,
      "y": 8,
      "z": 3,
      "name": "Rock_Slate",
      "rotation": 2
    },
    {
      "x": -9,
      "y": 2,
      "z": 4,
      "name": "Rock_Slate",
      "rotation": 2
    },
    {
      "x": -9,
      "y": 3,
      "z": 4,
      "name": "Rock_Slate_Brick_Smooth"
    },
    {
      "x": -9,
      "y": 6,
      "z": 4,
      "name": "Rock_Slate",
      "rotation": 2
    },
    {
      "x": -9,
      "y": 7,
      "z": 4,
      "name": "Rock_Slate",
      "rotation": 2
    },
    {
      "x": -9,
      "y": 8,
      "z": 4,
      "name": "Rock_Slate"
    },
    {
      "x": -9,
      "y": 1,
      "z": 5,
      "name": "Rock_Slate_Brick_Wall"
    },
    {
      "x": -9,
      "y": 2,
      "z": 5,
      "name": "Rock_Slate",
      "rotation": 2
    },
    {
      "x": -9,
      "y": 3,
      "z": 5,
      "name": "Rock_Slate_Brick_Smooth"
    },
    {
      "x": -9,
      "y": 4,
      "z": 5,
      "name": "Furniture_Jungle_Chair"
    },
    {
      "x": -9,
      "y": 5,
      "z": 5,
      "name": "Furniture_Jungle_Chair",
      "filler": 1024
    },
    {
      "x": -9,
      "y": 7,
      "z": 5,
      "name": "Rock_Slate",
      "rotation": 2
    },
    {
      "x": -9,
      "y": 8,
      "z": 5,
      "name": "Rock_Slate_Brick_Half"
    },
    {
      "x": -9,
      "y": 0,
      "z": 6,
      "name": "Furniture_Human_Ruins_Table",
      "filler": 31744,
      "rotation": 4
    },
    {
      "x": -9,
      "y": 1,
      "z": 6,
      "name": "Furniture_Human_Ruins_Table",
      "rotation": 4
    },
    {
      "x": -9,
      "y": 2,
      "z": 6,
      "name": "Rock_Slate",
      "rotation": 2
    },
    {
      "x": -9,
      "y": 3,
      "z": 6,
      "name": "Rock_Slate",
      "rotation": 2
    },
    {
      "x": -9,
      "y": 6,
      "z": 6,
      "name": "Rock_Slate_Brick_Smooth_Half",
      "rotation": 8
    },
    {
      "x": -9,
      "y": 8,
      "z": 6,
      "name": "Rock_Slate_Brick_Smooth_Half"
    },
    {
      "x": -9,
      "y": 1,
      "z": 7,
      "name": "Rock_Slate_Brick_Smooth_Half",
      "rotation": 4
    },
    {
      "x": -9,
      "y": 2,
      "z": 7,
      "name": "Rock_Slate",
      "rotation": 2
    },
    {
      "x": -9,
      "y": 3,
      "z": 7,
      "name": "Rock_Slate",
      "rotation": 2
    },
    {
      "x": -9,
      "y": 4,
      "z": 7,
      "name": "Rock_Slate_Brick_Smooth"
    },
    {
      "x": -9,
      "y": 5,
      "z": 7,
      "name": "*Furniture_Temple_Dark_Trapdoor_State_Definitions_CloseDoorOut",
      "rotation": 2
    },
    {
      "x": -9,
      "y": 6,
      "z": 7,
      "name": "Rock_Slate"
    },
    {
      "x": -9,
      "y": 7,
      "z": 7,
      "name": "Build_Black_Roof"
    },
    {
      "x": -9,
      "y": 10,
      "z": 7,
      "name": "Prototype_Rock_Concrete_Brick_Roof_Flat",
      "rotation": 1
    },
    {
      "x": -9,
      "y": 10,
      "z": 8,
      "name": "Prototype_Rock_Concrete_Brick_Roof_Flat",
      "rotation": 1
    },
    {
      "x": -9,
      "y": 10,
      "z": 9,
      "name": "Prototype_Rock_Concrete_Brick_Roof_Flat",
      "rotation": 1
    },
    {
      "x": -9,
      "y": 10,
      "z": 10,
      "name": "Prototype_Rock_Concrete_Brick_Roof_Flat"
    },
    {
      "x": -8,
      "y": 1,
      "z": 0,
      "name": "Rock_Slate_Brick_Half",
      "rotation": 6
    },
    {
      "x": -8,
      "y": 2,
      "z": 0,
      "name": "Rock_Slate",
      "rotation": 2
    },
    {
      "x": -8,
      "y": 3,
      "z": 0,
      "name": "Rock_Slate",
      "rotation": 2
    },
    {
      "x": -8,
      "y": 4,
      "z": 0,
      "name": "Rock_Slate",
      "rotation": 2
    },
    {
      "x": -8,
      "y": 5,
      "z": 0,
      "name": "Rock_Slate",
      "rotation": 2
    },
    {
      "x": -8,
      "y": 6,
      "z": 0,
      "name": "Rock_Slate",
      "rotation": 2
    },
    {
      "x": -8,
      "y": 7,
      "z": 0,
      "name": "*Build_Black_Roof_State_Definitions_Inverted_Corner_Right",
      "rotation": 3
    },
    {
      "x": -8,
      "y": 10,
      "z": 0,
      "name": "Prototype_Rock_Concrete_Brick_Roof_Flat",
      "rotation": 1
    },
    {
      "x": -8,
      "y": 0,
      "z": 1,
      "name": "Furniture_Human_Ruins_Table",
      "filler": 31744,
      "rotation": 6
    },
    {
      "x": -8,
      "y": 1,
      "z": 1,
      "name": "Furniture_Human_Ruins_Table",
      "rotation": 6
    },
    {
      "x": -8,
      "y": 2,
      "z": 1,
      "name": "Rock_Slate",
      "rotation": 2
    },
    {
      "x": -8,
      "y": 3,
      "z": 1,
      "name": "Rock_Slate",
      "rotation": 2
    },
    {
      "x": -8,
      "y": 6,
      "z": 1,
      "name": "Rock_Slate_Brick_Smooth"
    },
    {
      "x": -8,
      "y": 8,
      "z": 1,
      "name": "Rock_Slate_Brick_Smooth_Half"
    },
    {
      "x": -8,
      "y": 10,
      "z": 1,
      "name": "Prototype_Rock_Concrete_Brick_Roof_Flat",
      "rotation": 1
    },
    {
      "x": -8,
      "y": 1,
      "z": 2,
      "name": "Rock_Slate_Brick_Wall"
    },
    {
      "x": -8,
      "y": 2,
      "z": 2,
      "name": "Rock_Slate",
      "rotation": 2
    },
    {
      "x": -8,
      "y": 3,
      "z": 2,
      "name": "Rock_Slate",
      "rotation": 2
    },
    {
      "x": -8,
      "y": 6,
      "z": 2,
      "name": "Rock_Slate_Brick_Smooth"
    },
    {
      "x": -8,
      "y": 7,
      "z": 2,
      "name": "Rock_Slate",
      "rotation": 2
    },
    {
      "x": -8,
      "y": 8,
      "z": 2,
      "name": "Build_Black_Roof",
      "rotation": 3
    },
    {
      "x": -8,
      "y": 1,
      "z": 3,
      "name": "Rock_Slate_Brick_Roof_Flat",
      "rotation": 33
    },
    {
      "x": -8,
      "y": 2,
      "z": 3,
      "name": "Rock_Slate",
      "rotation": 2
    },
    {
      "x": -8,
      "y": 3,
      "z": 3,
      "name": "Rock_Slate_Brick_Smooth"
    },
    {
      "x": -8,
      "y": 7,
      "z": 3,
      "name": "Rock_Slate_Brick_Smooth"
    },
    {
      "x": -8,
      "y": 8,
      "z": 3,
      "name": "Rock_Slate",
      "rotation": 2
    },
    {
      "x": -8,
      "y": 1,
      "z": 4,
      "name": "Rock_Slate_Brick_Roof_Flat",
      "rotation": 33
    },
    {
      "x": -8,
      "y": 2,
      "z": 4,
      "name": "Rock_Slate",
      "rotation": 2
    },
    {
      "x": -8,
      "y": 3,
      "z": 4,
      "name": "Rock_Slate_Brick_Smooth"
    },
    {
      "x": -8,
      "y": 7,
      "z": 4,
      "name": "Rock_Slate_Brick_Smooth"
    },
    {
      "x": -8,
      "y": 8,
      "z": 4,
      "name": "Rock_Slate",
      "rotation": 2
    },
    {
      "x": -8,
      "y": 1,
      "z": 5,
      "name": "Rock_Slate_Brick_Wall",
      "rotation": 2
    },
    {
      "x": -8,
      "y": 2,
      "z": 5,
      "name": "Rock_Slate",
      "rotation": 2
    },
    {
      "x": -8,
      "y": 3,
      "z": 5,
      "name": "Rock_Slate",
      "rotation": 2
    },
    {
      "x": -8,
      "y": 6,
      "z": 5,
      "name": "Rock_Slate_Brick_Smooth"
    },
    {
      "x": -8,
      "y": 7,
      "z": 5,
      "name": "Rock_Slate",
      "rotation": 2
    },
    {
      "x": -8,
      "y": 8,
      "z": 5,
      "name": "Build_Black_Roof",
      "rotation": 3
    },
    {
      "x": -8,
      "y": 10,
      "z": 5,
      "name": "Prototype_Rock_Concrete_Brick_Roof_Flat",
      "rotation": 3
    },
    {
      "x": -8,
      "y": 0,
      "z": 6,
      "name": "Furniture_Human_Ruins_Table",
      "filler": 31745,
      "rotation": 4
    },
    {
      "x": -8,
      "y": 1,
      "z": 6,
      "name": "Furniture_Human_Ruins_Table",
      "filler": 1,
      "rotation": 4
    },
    {
      "x": -8,
      "y": 2,
      "z": 6,
      "name": "Rock_Slate",
      "rotation": 2
    },
    {
      "x": -8,
      "y": 3,
      "z": 6,
      "name": "Rock_Slate",
      "rotation": 2
    },
    {
      "x": -8,
      "y": 6,
      "z": 6,
      "name": "Rock_Slate_Brick_Smooth"
    },
    {
      "x": -8,
      "y": 8,
      "z": 6,
      "name": "Rock_Slate_Brick_Smooth_Half"
    },
    {
      "x": -8,
      "y": 10,
      "z": 6,
      "name": "Prototype_Rock_Concrete_Brick_Roof_Flat"
    },
    {
      "x": -8,
      "y": 1,
      "z": 7,
      "name": "Rock_Slate_Brick_Half",
      "rotation": 4
    },
    {
      "x": -8,
      "y": 2,
      "z": 7,
      "name": "Rock_Slate",
      "rotation": 2
    },
    {
      "x": -8,
      "y": 3,
      "z": 7,
      "name": "Rock_Slate",
      "rotation": 2
    },
    {
      "x": -8,
      "y": 4,
      "z": 7,
      "name": "Rock_Slate",
      "rotation": 2
    },
    {
      "x": -8,
      "y": 5,
      "z": 7,
      "name": "Rock_Slate"
    },
    {
      "x": -8,
      "y": 6,
      "z": 7,
      "name": "Rock_Slate"
    },
    {
      "x": -8,
      "y": 7,
      "z": 7,
      "name": "*Build_Black_Roof_State_Definitions_Inverted_Corner_Left",
      "rotation": 3
    },
    {
      "x": -8,
      "y": 10,
      "z": 7,
      "name": "Prototype_Rock_Concrete_Brick_Roof_Flat",
      "rotation": 1
    },
    {
      "x": -8,
      "y": 10,
      "z": 8,
      "name": "Prototype_Rock_Concrete_Brick_Roof_Flat",
      "rotation": 1
    },
    {
      "x": -7,
      "y": 2,
      "z": 0,
      "name": "Rock_Slate",
      "rotation": 2
    },
    {
      "x": -7,
      "y": 3,
      "z": 0,
      "name": "Rock_Slate",
      "rotation": 2
    },
    {
      "x": -7,
      "y": 4,
      "z": 0,
      "name": "Rock_Slate_Brick_Smooth"
    },
    {
      "x": -7,
      "y": 5,
      "z": 0,
      "name": "Rock_Slate_Brick_Smooth"
    },
    {
      "x": -7,
      "y": 6,
      "z": 0,
      "name": "Rock_Slate_Brick_Smooth"
    },
    {
      "x": -7,
      "y": 7,
      "z": 0,
      "name": "Rock_Slate"
    },
    {
      "x": -7,
      "y": 10,
      "z": 0,
      "name": "Prototype_Rock_Concrete_Brick_Roof_Flat",
      "rotation": 1
    },
    {
      "x": -7,
      "y": 1,
      "z": 1,
      "name": "Build_Black_Roof",
      "rotation": 33
    },
    {
      "x": -7,
      "y": 2,
      "z": 1,
      "name": "Rock_Slate",
      "rotation": 2
    },
    {
      "x": -7,
      "y": 3,
      "z": 1,
      "name": "Rock_Slate",
      "rotation": 2
    },
    {
      "x": -7,
      "y": 6,
      "z": 1,
      "name": "Build_Lightsource_YellowLight",
      "rotation": 5
    },
    {
      "x": -7,
      "y": 7,
      "z": 1,
      "name": "Rock_Slate"
    },
    {
      "x": -7,
      "y": 8,
      "z": 1,
      "name": "Rock_Slate_Brick_Half"
    },
    {
      "x": -7,
      "y": 10,
      "z": 1,
      "name": "Prototype_Rock_Concrete_Brick_Roof_Flat",
      "rotation": 2
    },
    {
      "x": -7,
      "y": 2,
      "z": 2,
      "name": "Rock_Slate",
      "rotation": 2
    },
    {
      "x": -7,
      "y": 3,
      "z": 2,
      "name": "Rock_Slate",
      "rotation": 2
    },
    {
      "x": -7,
      "y": 7,
      "z": 2,
      "name": "Rock_Slate",
      "rotation": 2
    },
    {
      "x": -7,
      "y": 8,
      "z": 2,
      "name": "Rock_Slate",
      "rotation": 2
    },
    {
      "x": -7,
      "y": 10,
      "z": 2,
      "name": "Prototype_Rock_Concrete_Brick_Roof_Flat",
      "rotation": 2
    },
    {
      "x": -7,
      "y": 2,
      "z": 3,
      "name": "Rock_Slate",
      "rotation": 2
    },
    {
      "x": -7,
      "y": 3,
      "z": 3,
      "name": "Rock_Slate_Brick_Smooth"
    },
    {
      "x": -7,
      "y": 7,
      "z": 3,
      "name": "Rock_Slate_Brick_Smooth"
    },
    {
      "x": -7,
      "y": 8,
      "z": 3,
      "name": "Rock_Slate",
      "rotation": 2
    },
    {
      "x": -7,
      "y": 2,
      "z": 4,
      "name": "Rock_Slate",
      "rotation": 2
    },
    {
      "x": -7,
      "y": 3,
      "z": 4,
      "name": "Rock_Slate_Brick_Smooth"
    },
    {
      "x": -7,
      "y": 7,
      "z": 4,
      "name": "Rock_Slate_Brick_Smooth"
    },
    {
      "x": -7,
      "y": 8,
      "z": 4,
      "name": "Rock_Slate",
      "rotation": 2
    },
    {
      "x": -7,
      "y": 10,
      "z": 4,
      "name": "Prototype_Rock_Concrete_Brick_Roof_Flat",
      "rotation": 3
    },
    {
      "x": -7,
      "y": 2,
      "z": 5,
      "name": "Rock_Slate",
      "rotation": 2
    },
    {
      "x": -7,
      "y": 3,
      "z": 5,
      "name": "Rock_Slate",
      "rotation": 2
    },
    {
      "x": -7,
      "y": 7,
      "z": 5,
      "name": "Rock_Slate",
      "rotation": 2
    },
    {
      "x": -7,
      "y": 8,
      "z": 5,
      "name": "Rock_Slate"
    },
    {
      "x": -7,
      "y": 10,
      "z": 5,
      "name": "Prototype_Rock_Concrete_Brick_Roof_Flat",
      "rotation": 3
    },
    {
      "x": -7,
      "y": 1,
      "z": 6,
      "name": "Build_Black_Roof",
      "rotation": 33
    },
    {
      "x": -7,
      "y": 2,
      "z": 6,
      "name": "Rock_Slate",
      "rotation": 2
    },
    {
      "x": -7,
      "y": 3,
      "z": 6,
      "name": "Rock_Slate",
      "rotation": 2
    },
    {
      "x": -7,
      "y": 6,
      "z": 6,
      "name": "Build_Lightsource_YellowLight",
      "rotation": 5
    },
    {
      "x": -7,
      "y": 7,
      "z": 6,
      "name": "Rock_Slate"
    },
    {
      "x": -7,
      "y": 8,
      "z": 6,
      "name": "Rock_Slate_Brick_Half"
    },
    {
      "x": -7,
      "y": 10,
      "z": 6,
      "name": "Prototype_Rock_Concrete_Brick_Roof_Flat"
    },
    {
      "x": -7,
      "y": 2,
      "z": 7,
      "name": "Rock_Slate",
      "rotation": 2
    },
    {
      "x": -7,
      "y": 3,
      "z": 7,
      "name": "Rock_Slate",
      "rotation": 2
    },
    {
      "x": -7,
      "y": 4,
      "z": 7,
      "name": "Rock_Slate_Brick_Smooth"
    },
    {
      "x": -7,
      "y": 5,
      "z": 7,
      "name": "Rock_Slate_Brick_Smooth"
    },
    {
      "x": -7,
      "y": 6,
      "z": 7,
      "name": "Rock_Slate_Brick_Smooth"
    },
    {
      "x": -7,
      "y": 7,
      "z": 7,
      "name": "Rock_Slate"
    },
    {
      "x": -7,
      "y": 10,
      "z": 7,
      "name": "Prototype_Rock_Concrete_Brick_Roof_Flat"
    },
    {
      "x": -6,
      "y": 2,
      "z": 0,
      "name": "Rock_Slate_Brick_Smooth_Half",
      "rotation": 6
    },
    {
      "x": -6,
      "y": 3,
      "z": 0,
      "name": "Rock_Slate",
      "rotation": 2
    },
    {
      "x": -6,
      "y": 4,
      "z": 0,
      "name": "*Helicopter_Door_State_Definitions_CloseDoorOut"
    },
    {
      "x": -6,
      "y": 5,
      "z": 0,
      "name": "*Helicopter_Door_State_Definitions_CloseDoorOut",
      "filler": 1024
    },
    {
      "x": -6,
      "y": 6,
      "z": 0,
      "name": "*Helicopter_Door_State_Definitions_CloseDoorOut",
      "filler": 2048
    },
    {
      "x": -6,
      "y": 7,
      "z": 0,
      "name": "Rock_Slate",
      "rotation": 2
    },
    {
      "x": -6,
      "y": 2,
      "z": 1,
      "name": "Rock_Slate",
      "rotation": 2
    },
    {
      "x": -6,
      "y": 3,
      "z": 1,
      "name": "Rock_Slate_Brick_Smooth"
    },
    {
      "x": -6,
      "y": 6,
      "z": 1,
      "name": "Rock_Slate_Brick_Roof_Flat",
      "rotation": 10
    },
    {
      "x": -6,
      "y": 7,
      "z": 1,
      "name": "Rock_Slate",
      "rotation": 2
    },
    {
      "x": -6,
      "y": 8,
      "z": 1,
      "name": "Rock_Slate_Brick_Half"
    },
    {
      "x": -6,
      "y": 10,
      "z": 1,
      "name": "Prototype_Rock_Concrete_Brick_Roof_Flat",
      "rotation": 2
    },
    {
      "x": -6,
      "y": 2,
      "z": 2,
      "name": "Rock_Slate",
      "rotation": 2
    },
    {
      "x": -6,
      "y": 3,
      "z": 2,
      "name": "Rock_Slate",
      "rotation": 2
    },
    {
      "x": -6,
      "y": 7,
      "z": 2,
      "name": "Rock_Slate",
      "rotation": 2
    },
    {
      "x": -6,
      "y": 8,
      "z": 2,
      "name": "Rock_Slate",
      "rotation": 2
    },
    {
      "x": -6,
      "y": 10,
      "z": 2,
      "name": "Prototype_Rock_Concrete_Brick_Roof_Flat",
      "rotation": 2
    },
    {
      "x": -6,
      "y": 2,
      "z": 3,
      "name": "Rock_Slate",
      "rotation": 2
    },
    {
      "x": -6,
      "y": 3,
      "z": 3,
      "name": "Rock_Slate_Brick_Smooth"
    },
    {
      "x": -6,
      "y": 7,
      "z": 3,
      "name": "Rock_Slate_Brick_Smooth"
    },
    {
      "x": -6,
      "y": 8,
      "z": 3,
      "name": "Rock_Slate",
      "rotation": 2
    },
    {
      "x": -6,
      "y": 10,
      "z": 3,
      "name": "Prototype_Rock_Concrete_Brick_Roof_Flat"
    },
    {
      "x": -6,
      "y": 2,
      "z": 4,
      "name": "Rock_Slate",
      "rotation": 2
    },
    {
      "x": -6,
      "y": 3,
      "z": 4,
      "name": "Rock_Slate_Brick_Smooth"
    },
    {
      "x": -6,
      "y": 7,
      "z": 4,
      "name": "Rock_Slate_Brick_Smooth"
    },
    {
      "x": -6,
      "y": 8,
      "z": 4,
      "name": "Rock_Slate",
      "rotation": 2
    },
    {
      "x": -6,
      "y": 10,
      "z": 4,
      "name": "Prototype_Rock_Concrete_Brick_Roof_Flat",
      "rotation": 3
    },
    {
      "x": -6,
      "y": 2,
      "z": 5,
      "name": "Rock_Slate",
      "rotation": 2
    },
    {
      "x": -6,
      "y": 3,
      "z": 5,
      "name": "Rock_Slate",
      "rotation": 2
    },
    {
      "x": -6,
      "y": 7,
      "z": 5,
      "name": "Rock_Slate",
      "rotation": 2
    },
    {
      "x": -6,
      "y": 8,
      "z": 5,
      "name": "Rock_Slate",
      "rotation": 2
    },
    {
      "x": -6,
      "y": 10,
      "z": 5,
      "name": "Prototype_Rock_Concrete_Brick_Roof_Flat",
      "rotation": 3
    },
    {
      "x": -6,
      "y": 2,
      "z": 6,
      "name": "Rock_Slate",
      "rotation": 2
    },
    {
      "x": -6,
      "y": 3,
      "z": 6,
      "name": "Rock_Slate_Brick_Smooth"
    },
    {
      "x": -6,
      "y": 6,
      "z": 6,
      "name": "Rock_Slate_Brick_Roof_Flat",
      "rotation": 8
    },
    {
      "x": -6,
      "y": 7,
      "z": 6,
      "name": "Rock_Slate",
      "rotation": 2
    },
    {
      "x": -6,
      "y": 8,
      "z": 6,
      "name": "Rock_Slate_Brick_Half"
    },
    {
      "x": -6,
      "y": 2,
      "z": 7,
      "name": "Rock_Slate_Brick_Smooth_Half",
      "rotation": 4
    },
    {
      "x": -6,
      "y": 3,
      "z": 7,
      "name": "Rock_Slate",
      "rotation": 2
    },
    {
      "x": -6,
      "y": 4,
      "z": 7,
      "name": "*Helicopter_Door_State_Definitions_CloseDoorOut",
      "filler": 30,
      "rotation": 2
    },
    {
      "x": -6,
      "y": 5,
      "z": 7,
      "name": "*Helicopter_Door_State_Definitions_CloseDoorOut",
      "filler": 1054,
      "rotation": 2
    },
    {
      "x": -6,
      "y": 6,
      "z": 7,
      "name": "*Helicopter_Door_State_Definitions_CloseDoorOut",
      "filler": 2078,
      "rotation": 2
    },
    {
      "x": -6,
      "y": 7,
      "z": 7,
      "name": "Rock_Slate",
      "rotation": 2
    },
    {
      "x": -5,
      "y": 10,
      "z": -6,
      "name": "Prototype_Rock_Concrete_Brick_Roof_Flat"
    },
    {
      "x": -5,
      "y": 10,
      "z": -5,
      "name": "Prototype_Rock_Concrete_Brick_Roof_Flat"
    },
    {
      "x": -5,
      "y": 10,
      "z": -4,
      "name": "Prototype_Rock_Concrete_Brick_Roof_Flat"
    },
    {
      "x": -5,
      "y": 10,
      "z": -3,
      "name": "Prototype_Rock_Concrete_Brick_Roof_Flat"
    },
    {
      "x": -5,
      "y": 10,
      "z": -2,
      "name": "Prototype_Rock_Concrete_Brick_Roof_Flat",
      "rotation": 2
    },
    {
      "x": -5,
      "y": 10,
      "z": -1,
      "name": "Prototype_Rock_Concrete_Brick_Roof_Flat",
      "rotation": 2
    },
    {
      "x": -5,
      "y": 2,
      "z": 0,
      "name": "Rock_Slate",
      "rotation": 2
    },
    {
      "x": -5,
      "y": 3,
      "z": 0,
      "name": "Rock_Slate",
      "rotation": 2
    },
    {
      "x": -5,
      "y": 4,
      "z": 0,
      "name": "*Helicopter_Door_State_Definitions_CloseDoorOut",
      "filler": 1
    },
    {
      "x": -5,
      "y": 5,
      "z": 0,
      "name": "*Helicopter_Door_State_Definitions_CloseDoorOut",
      "filler": 1025
    },
    {
      "x": -5,
      "y": 6,
      "z": 0,
      "name": "*Helicopter_Door_State_Definitions_CloseDoorOut",
      "filler": 2049
    },
    {
      "x": -5,
      "y": 7,
      "z": 0,
      "name": "Rock_Slate",
      "rotation": 2
    },
    {
      "x": -5,
      "y": 10,
      "z": 0,
      "name": "Prototype_Rock_Concrete_Brick_Roof_Flat",
      "rotation": 2
    },
    {
      "x": -5,
      "y": 2,
      "z": 1,
      "name": "Rock_Slate",
      "rotation": 2
    },
    {
      "x": -5,
      "y": 3,
      "z": 1,
      "name": "Rock_Slate_Brick_Smooth"
    },
    {
      "x": -5,
      "y": 7,
      "z": 1,
      "name": "Rock_Slate_Brick_Smooth"
    },
    {
      "x": -5,
      "y": 8,
      "z": 1,
      "name": "Rock_Slate_Brick_Half"
    },
    {
      "x": -5,
      "y": 10,
      "z": 1,
      "name": "Prototype_Rock_Concrete_Brick_Roof_Flat",
      "rotation": 2
    },
    {
      "x": -5,
      "y": 1,
      "z": 2,
      "name": "Rock_Slate_Brick_Roof_Flat",
      "rotation": 35
    },
    {
      "x": -5,
      "y": 2,
      "z": 2,
      "name": "Rock_Slate",
      "rotation": 2
    },
    {
      "x": -5,
      "y": 3,
      "z": 2,
      "name": "Rock_Slate",
      "rotation": 2
    },
    {
      "x": -5,
      "y": 7,
      "z": 2,
      "name": "Rock_Slate_Brick_Smooth"
    },
    {
      "x": -5,
      "y": 8,
      "z": 2,
      "name": "Rock_Slate",
      "rotation": 2
    },
    {
      "x": -5,
      "y": 10,
      "z": 2,
      "name": "Rock_Slate_Brick_Half"
    },
    {
      "x": -5,
      "y": 2,
      "z": 3,
      "name": "Rock_Slate",
      "rotation": 2
    },
    {
      "x": -5,
      "y": 3,
      "z": 3,
      "name": "Rock_Slate_Brick_Smooth"
    },
    {
      "x": -5,
      "y": 6,
      "z": 3,
      "name": "Metal_Iron_Roof_Flat",
      "rotation": 33
    },
    {
      "x": -5,
      "y": 7,
      "z": 3,
      "name": "Rock_Slate_Brick_Smooth"
    },
    {
      "x": -5,
      "y": 8,
      "z": 3,
      "name": "Rock_Slate",
      "rotation": 2
    },
    {
      "x": -5,
      "y": 9,
      "z": 3,
      "name": "Rock_Slate_Brick_Wall",
      "rotation": 2
    },
    {
      "x": -5,
      "y": 10,
      "z": 3,
      "name": "Rock_Calcite"
    },
    {
      "x": -5,
      "y": 2,
      "z": 4,
      "name": "Rock_Slate",
      "rotation": 2
    },
    {
      "x": -5,
      "y": 3,
      "z": 4,
      "name": "Rock_Slate_Brick_Smooth"
    },
    {
      "x": -5,
      "y": 6,
      "z": 4,
      "name": "Metal_Iron_Roof_Flat",
      "rotation": 33
    },
    {
      "x": -5,
      "y": 7,
      "z": 4,
      "name": "Rock_Slate_Brick_Smooth"
    },
    {
      "x": -5,
      "y": 8,
      "z": 4,
      "name": "Rock_Slate",
      "rotation": 2
    },
    {
      "x": -5,
      "y": 10,
      "z": 4,
      "name": "Prototype_Rock_Concrete_Brick_Roof_Flat"
    },
    {
      "x": -5,
      "y": 1,
      "z": 5,
      "name": "Rock_Slate_Brick_Roof_Flat",
      "rotation": 35
    },
    {
      "x": -5,
      "y": 2,
      "z": 5,
      "name": "Rock_Slate",
      "rotation": 2
    },
    {
      "x": -5,
      "y": 3,
      "z": 5,
      "name": "Rock_Slate",
      "rotation": 2
    },
    {
      "x": -5,
      "y": 7,
      "z": 5,
      "name": "Rock_Slate_Brick_Smooth"
    },
    {
      "x": -5,
      "y": 8,
      "z": 5,
      "name": "Rock_Slate",
      "rotation": 2
    },
    {
      "x": -5,
      "y": 2,
      "z": 6,
      "name": "Rock_Slate",
      "rotation": 2
    },
    {
      "x": -5,
      "y": 3,
      "z": 6,
      "name": "Rock_Slate_Brick_Smooth"
    },
    {
      "x": -5,
      "y": 7,
      "z": 6,
      "name": "Rock_Slate_Brick_Smooth"
    },
    {
      "x": -5,
      "y": 8,
      "z": 6,
      "name": "Rock_Slate_Brick_Half"
    },
    {
      "x": -5,
      "y": 2,
      "z": 7,
      "name": "Rock_Slate"
    },
    {
      "x": -5,
      "y": 3,
      "z": 7,
      "name": "Rock_Slate",
      "rotation": 2
    },
    {
      "x": -5,
      "y": 4,
      "z": 7,
      "name": "*Helicopter_Door_State_Definitions_CloseDoorOut",
      "filler": 31,
      "rotation": 2
    },
    {
      "x": -5,
      "y": 5,
      "z": 7,
      "name": "*Helicopter_Door_State_Definitions_CloseDoorOut",
      "filler": 1055,
      "rotation": 2
    },
    {
      "x": -5,
      "y": 6,
      "z": 7,
      "name": "*Helicopter_Door_State_Definitions_CloseDoorOut",
      "filler": 2079,
      "rotation": 2
    },
    {
      "x": -5,
      "y": 7,
      "z": 7,
      "name": "Rock_Slate",
      "rotation": 2
    },
    {
      "x": -4,
      "y": 10,
      "z": -14,
      "name": "Prototype_Rock_Concrete_Brick_Roof_Flat"
    },
    {
      "x": -4,
      "y": 10,
      "z": -13,
      "name": "Prototype_Rock_Concrete_Brick_Roof_Flat"
    },
    {
      "x": -4,
      "y": 10,
      "z": -12,
      "name": "Prototype_Rock_Concrete_Brick_Roof_Flat"
    },
    {
      "x": -4,
      "y": 10,
      "z": -11,
      "name": "Prototype_Rock_Concrete_Brick_Roof_Flat"
    },
    {
      "x": -4,
      "y": 10,
      "z": -10,
      "name": "Prototype_Rock_Concrete_Brick_Roof_Flat"
    },
    {
      "x": -4,
      "y": 10,
      "z": -9,
      "name": "Prototype_Rock_Concrete_Brick_Roof_Flat"
    },
    {
      "x": -4,
      "y": 10,
      "z": -8,
      "name": "Prototype_Rock_Concrete_Brick_Roof_Flat"
    },
    {
      "x": -4,
      "y": 10,
      "z": -7,
      "name": "Prototype_Rock_Concrete_Brick_Roof_Flat"
    },
    {
      "x": -4,
      "y": 10,
      "z": -6,
      "name": "Prototype_Rock_Concrete_Brick_Roof_Flat"
    },
    {
      "x": -4,
      "y": 10,
      "z": -5,
      "name": "Prototype_Rock_Concrete_Brick_Roof_Flat"
    },
    {
      "x": -4,
      "y": 10,
      "z": -4,
      "name": "Prototype_Rock_Concrete_Brick_Roof_Flat"
    },
    {
      "x": -4,
      "y": 10,
      "z": -3,
      "name": "Prototype_Rock_Concrete_Brick_Roof_Flat"
    },
    {
      "x": -4,
      "y": 10,
      "z": -2,
      "name": "Prototype_Rock_Concrete_Brick_Roof_Flat",
      "rotation": 2
    },
    {
      "x": -4,
      "y": 10,
      "z": -1,
      "name": "Prototype_Rock_Concrete_Brick_Roof_Flat",
      "rotation": 2
    },
    {
      "x": -4,
      "y": 2,
      "z": 0,
      "name": "Rock_Slate_Brick_Half",
      "rotation": 6
    },
    {
      "x": -4,
      "y": 3,
      "z": 0,
      "name": "Rock_Slate",
      "rotation": 2
    },
    {
      "x": -4,
      "y": 4,
      "z": 0,
      "name": "*Helicopter_Door_State_Definitions_CloseDoorOut",
      "filler": 2
    },
    {
      "x": -4,
      "y": 5,
      "z": 0,
      "name": "*Helicopter_Door_State_Definitions_CloseDoorOut",
      "filler": 1026
    },
    {
      "x": -4,
      "y": 6,
      "z": 0,
      "name": "*Helicopter_Door_State_Definitions_CloseDoorOut",
      "filler": 2050
    },
    {
      "x": -4,
      "y": 7,
      "z": 0,
      "name": "Rock_Slate",
      "rotation": 2
    },
    {
      "x": -4,
      "y": 10,
      "z": 0,
      "name": "Prototype_Rock_Concrete_Brick_Roof_Flat",
      "rotation": 2
    },
    {
      "x": -4,
      "y": 2,
      "z": 1,
      "name": "Rock_Slate",
      "rotation": 2
    },
    {
      "x": -4,
      "y": 3,
      "z": 1,
      "name": "Rock_Slate_Brick_Smooth"
    },
    {
      "x": -4,
      "y": 7,
      "z": 1,
      "name": "Rock_Slate_Brick_Smooth"
    },
    {
      "x": -4,
      "y": 8,
      "z": 1,
      "name": "Rock_Slate_Brick_Half"
    },
    {
      "x": -4,
      "y": 10,
      "z": 1,
      "name": "Prototype_Rock_Concrete_Brick_Roof_Flat",
      "rotation": 2
    },
    {
      "x": -4,
      "y": 1,
      "z": 2,
      "name": "Rock_Slate_Brick_Roof_Flat",
      "rotation": 35
    },
    {
      "x": -4,
      "y": 2,
      "z": 2,
      "name": "Rock_Slate",
      "rotation": 2
    },
    {
      "x": -4,
      "y": 3,
      "z": 2,
      "name": "Rock_Slate",
      "rotation": 2
    },
    {
      "x": -4,
      "y": 7,
      "z": 2,
      "name": "Rock_Slate_Brick_Smooth"
    },
    {
      "x": -4,
      "y": 8,
      "z": 2,
      "name": "Rock_Slate",
      "rotation": 2
    },
    {
      "x": -4,
      "y": 9,
      "z": 2,
      "name": "Rock_Slate_Brick_Wall",
      "rotation": 2
    },
    {
      "x": -4,
      "y": 10,
      "z": 2,
      "name": "Rock_Calcite"
    },
    {
      "x": -4,
      "y": 2,
      "z": 3,
      "name": "Rock_Slate",
      "rotation": 2
    },
    {
      "x": -4,
      "y": 3,
      "z": 3,
      "name": "Rock_Slate_Brick_Smooth"
    },
    {
      "x": -4,
      "y": 6,
      "z": 3,
      "name": "Build_Grey_Roof_Flat",
      "rotation": 32
    },
    {
      "x": -4,
      "y": 7,
      "z": 3,
      "name": "Rock_Slate_Brick_Smooth"
    },
    {
      "x": -4,
      "y": 8,
      "z": 3,
      "name": "Rock_Slate",
      "rotation": 2
    },
    {
      "x": -4,
      "y": 9,
      "z": 3,
      "name": "Rock_Slate_Cobble_Wall"
    },
    {
      "x": -4,
      "y": 10,
      "z": 3,
      "name": "Rock_Slate_Brick_Half"
    },
    {
      "x": -4,
      "y": 2,
      "z": 4,
      "name": "Rock_Slate",
      "rotation": 2
    },
    {
      "x": -4,
      "y": 3,
      "z": 4,
      "name": "Rock_Slate_Brick_Smooth"
    },
    {
      "x": -4,
      "y": 6,
      "z": 4,
      "name": "Build_Grey_Roof_Flat",
      "rotation": 32
    },
    {
      "x": -4,
      "y": 7,
      "z": 4,
      "name": "Rock_Slate_Brick_Smooth"
    },
    {
      "x": -4,
      "y": 8,
      "z": 4,
      "name": "Rock_Slate",
      "rotation": 2
    },
    {
      "x": -4,
      "y": 10,
      "z": 4,
      "name": "Prototype_Rock_Concrete_Brick_Roof_Flat"
    },
    {
      "x": -4,
      "y": 1,
      "z": 5,
      "name": "Rock_Slate_Brick_Roof_Flat",
      "rotation": 35
    },
    {
      "x": -4,
      "y": 2,
      "z": 5,
      "name": "Rock_Slate",
      "rotation": 2
    },
    {
      "x": -4,
      "y": 3,
      "z": 5,
      "name": "Rock_Slate",
      "rotation": 2
    },
    {
      "x": -4,
      "y": 7,
      "z": 5,
      "name": "Rock_Slate_Brick_Smooth"
    },
    {
      "x": -4,
      "y": 8,
      "z": 5,
      "name": "Rock_Slate",
      "rotation": 2
    },
    {
      "x": -4,
      "y": 2,
      "z": 6,
      "name": "Rock_Slate",
      "rotation": 2
    },
    {
      "x": -4,
      "y": 3,
      "z": 6,
      "name": "Rock_Slate_Brick_Smooth"
    },
    {
      "x": -4,
      "y": 7,
      "z": 6,
      "name": "Rock_Slate_Brick_Smooth"
    },
    {
      "x": -4,
      "y": 8,
      "z": 6,
      "name": "Rock_Slate_Brick_Half"
    },
    {
      "x": -4,
      "y": 2,
      "z": 7,
      "name": "Rock_Slate_Brick_Half",
      "rotation": 4
    },
    {
      "x": -4,
      "y": 3,
      "z": 7,
      "name": "Rock_Slate",
      "rotation": 2
    },
    {
      "x": -4,
      "y": 4,
      "z": 7,
      "name": "*Helicopter_Door_State_Definitions_CloseDoorOut",
      "rotation": 2
    },
    {
      "x": -4,
      "y": 5,
      "z": 7,
      "name": "*Helicopter_Door_State_Definitions_CloseDoorOut",
      "filler": 1024,
      "rotation": 2
    },
    {
      "x": -4,
      "y": 6,
      "z": 7,
      "name": "*Helicopter_Door_State_Definitions_CloseDoorOut",
      "filler": 2048,
      "rotation": 2
    },
    {
      "x": -4,
      "y": 7,
      "z": 7,
      "name": "Rock_Slate",
      "rotation": 2
    },
    {
      "x": -3,
      "y": 10,
      "z": -15,
      "name": "Prototype_Rock_Concrete_Brick_Roof_Flat"
    },
    {
      "x": -3,
      "y": 10,
      "z": -14,
      "name": "Prototype_Rock_Concrete_Brick_Roof_Flat"
    },
    {
      "x": -3,
      "y": 10,
      "z": -13,
      "name": "Prototype_Rock_Concrete_Brick_Roof_Flat"
    },
    {
      "x": -3,
      "y": 10,
      "z": -12,
      "name": "Prototype_Rock_Concrete_Brick_Roof_Flat"
    },
    {
      "x": -3,
      "y": 10,
      "z": -11,
      "name": "Prototype_Rock_Concrete_Brick_Roof_Flat"
    },
    {
      "x": -3,
      "y": 10,
      "z": -10,
      "name": "Prototype_Rock_Concrete_Brick_Roof_Flat"
    },
    {
      "x": -3,
      "y": 10,
      "z": -9,
      "name": "Prototype_Rock_Concrete_Brick_Roof_Flat"
    },
    {
      "x": -3,
      "y": 10,
      "z": -8,
      "name": "Prototype_Rock_Concrete_Brick_Roof_Flat"
    },
    {
      "x": -3,
      "y": 10,
      "z": -7,
      "name": "Prototype_Rock_Concrete_Brick_Roof_Flat"
    },
    {
      "x": -3,
      "y": 10,
      "z": -6,
      "name": "Prototype_Rock_Concrete_Brick_Roof_Flat"
    },
    {
      "x": -3,
      "y": 2,
      "z": 0,
      "name": "Rock_Slate_Brick_Half",
      "rotation": 6
    },
    {
      "x": -3,
      "y": 3,
      "z": 0,
      "name": "Rock_Slate",
      "rotation": 2
    },
    {
      "x": -3,
      "y": 4,
      "z": 0,
      "name": "Rock_Slate_Brick_Smooth"
    },
    {
      "x": -3,
      "y": 5,
      "z": 0,
      "name": "Rock_Slate_Brick_Smooth"
    },
    {
      "x": -3,
      "y": 6,
      "z": 0,
      "name": "Rock_Slate_Brick_Smooth"
    },
    {
      "x": -3,
      "y": 7,
      "z": 0,
      "name": "Rock_Slate",
      "rotation": 2
    },
    {
      "x": -3,
      "y": 2,
      "z": 1,
      "name": "Rock_Slate",
      "rotation": 2
    },
    {
      "x": -3,
      "y": 3,
      "z": 1,
      "name": "Rock_Slate",
      "rotation": 2
    },
    {
      "x": -3,
      "y": 7,
      "z": 1,
      "name": "Rock_Slate",
      "rotation": 2
    },
    {
      "x": -3,
      "y": 8,
      "z": 1,
      "name": "Rock_Slate_Brick_Smooth_Half"
    },
    {
      "x": -3,
      "y": 1,
      "z": 2,
      "name": "Rock_Slate_Brick_Roof_Flat",
      "rotation": 35
    },
    {
      "x": -3,
      "y": 2,
      "z": 2,
      "name": "Rock_Slate",
      "rotation": 2
    },
    {
      "x": -3,
      "y": 3,
      "z": 2,
      "name": "Rock_Slate",
      "rotation": 2
    },
    {
      "x": -3,
      "y": 7,
      "z": 2,
      "name": "Rock_Slate",
      "rotation": 2
    },
    {
      "x": -3,
      "y": 8,
      "z": 2,
      "name": "Rock_Slate",
      "rotation": 2
    },
    {
      "x": -3,
      "y": 9,
      "z": 2,
      "name": "Rock_Slate_Brick_Smooth_Half"
    },
    {
      "x": -3,
      "y": 10,
      "z": 2,
      "name": "Prototype_Rock_Concrete_Brick_Roof_Flat",
      "rotation": 1
    },
    {
      "x": -3,
      "y": 2,
      "z": 3,
      "name": "Rock_Slate",
      "rotation": 2
    },
    {
      "x": -3,
      "y": 3,
      "z": 3,
      "name": "Rock_Slate_Brick_Smooth"
    },
    {
      "x": -3,
      "y": 7,
      "z": 3,
      "name": "Rock_Slate",
      "rotation": 2
    },
    {
      "x": -3,
      "y": 8,
      "z": 3,
      "name": "Rock_Slate",
      "rotation": 2
    },
    {
      "x": -3,
      "y": 9,
      "z": 3,
      "name": "Rock_Slate_Brick_Smooth_Half"
    },
    {
      "x": -3,
      "y": 10,
      "z": 3,
      "name": "Prototype_Rock_Concrete_Brick_Roof_Flat",
      "rotation": 1
    },
    {
      "x": -3,
      "y": 2,
      "z": 4,
      "name": "Rock_Slate",
      "rotation": 2
    },
    {
      "x": -3,
      "y": 3,
      "z": 4,
      "name": "Rock_Slate_Brick_Smooth"
    },
    {
      "x": -3,
      "y": 7,
      "z": 4,
      "name": "Rock_Slate",
      "rotation": 2
    },
    {
      "x": -3,
      "y": 8,
      "z": 4,
      "name": "Rock_Slate",
      "rotation": 2
    },
    {
      "x": -3,
      "y": 10,
      "z": 4,
      "name": "Prototype_Rock_Concrete_Brick_Roof_Flat",
      "rotation": 1
    },
    {
      "x": -3,
      "y": 1,
      "z": 5,
      "name": "Rock_Slate_Brick_Roof_Flat",
      "rotation": 35
    },
    {
      "x": -3,
      "y": 2,
      "z": 5,
      "name": "Rock_Slate",
      "rotation": 2
    },
    {
      "x": -3,
      "y": 3,
      "z": 5,
      "name": "Rock_Slate",
      "rotation": 2
    },
    {
      "x": -3,
      "y": 7,
      "z": 5,
      "name": "Rock_Slate",
      "rotation": 2
    },
    {
      "x": -3,
      "y": 8,
      "z": 5,
      "name": "Rock_Slate",
      "rotation": 2
    },
    {
      "x": -3,
      "y": 10,
      "z": 5,
      "name": "Prototype_Rock_Concrete_Brick_Roof_Flat",
      "rotation": 1
    },
    {
      "x": -3,
      "y": 2,
      "z": 6,
      "name": "Rock_Slate",
      "rotation": 2
    },
    {
      "x": -3,
      "y": 3,
      "z": 6,
      "name": "Rock_Slate",
      "rotation": 2
    },
    {
      "x": -3,
      "y": 7,
      "z": 6,
      "name": "Rock_Slate",
      "rotation": 2
    },
    {
      "x": -3,
      "y": 8,
      "z": 6,
      "name": "Rock_Slate_Brick_Smooth_Half"
    },
    {
      "x": -3,
      "y": 2,
      "z": 7,
      "name": "Rock_Slate_Brick_Half",
      "rotation": 4
    },
    {
      "x": -3,
      "y": 3,
      "z": 7,
      "name": "Rock_Slate",
      "rotation": 2
    },
    {
      "x": -3,
      "y": 4,
      "z": 7,
      "name": "Rock_Slate_Brick_Smooth"
    },
    {
      "x": -3,
      "y": 5,
      "z": 7,
      "name": "Rock_Slate_Brick_Smooth"
    },
    {
      "x": -3,
      "y": 6,
      "z": 7,
      "name": "Rock_Slate_Brick_Smooth"
    },
    {
      "x": -3,
      "y": 7,
      "z": 7,
      "name": "Rock_Slate",
      "rotation": 2
    },
    {
      "x": -2,
      "y": 3,
      "z": -1,
      "name": "Rock_Slate_Brick_Smooth_Half",
      "rotation": 6
    },
    {
      "x": -2,
      "y": 2,
      "z": 0,
      "name": "Rock_Slate_Brick_Half",
      "rotation": 6
    },
    {
      "x": -2,
      "y": 3,
      "z": 0,
      "name": "Rock_Slate",
      "rotation": 2
    },
    {
      "x": -2,
      "y": 4,
      "z": 0,
      "name": "Rock_Slate"
    },
    {
      "x": -2,
      "y": 5,
      "z": 0,
      "name": "Rock_Slate"
    },
    {
      "x": -2,
      "y": 6,
      "z": 0,
      "name": "Rock_Slate"
    },
    {
      "x": -2,
      "y": 7,
      "z": 0,
      "name": "Rock_Slate_Brick_Half",
      "rotation": 6
    },
    {
      "x": -2,
      "y": 2,
      "z": 1,
      "name": "Rock_Slate",
      "rotation": 2
    },
    {
      "x": -2,
      "y": 3,
      "z": 1,
      "name": "Rock_Slate",
      "rotation": 2
    },
    {
      "x": -2,
      "y": 4,
      "z": 1,
      "name": "Build_Black_Roof"
    },
    {
      "x": -2,
      "y": 5,
      "z": 1,
      "name": "Build_Black_Roof_Steep",
      "filler": 31744,
      "rotation": 32
    },
    {
      "x": -2,
      "y": 6,
      "z": 1,
      "name": "Build_Black_Roof_Steep",
      "rotation": 32
    },
    {
      "x": -2,
      "y": 7,
      "z": 1,
      "name": "Rock_Slate",
      "rotation": 2
    },
    {
      "x": -2,
      "y": 8,
      "z": 1,
      "name": "Rock_Slate_Brick_Smooth_Half"
    },
    {
      "x": -2,
      "y": 10,
      "z": 1,
      "name": "Prototype_Rock_Concrete_Brick_Roof_Flat",
      "rotation": 1
    },
    {
      "x": -2,
      "y": 2,
      "z": 2,
      "name": "Rock_Slate",
      "rotation": 2
    },
    {
      "x": -2,
      "y": 3,
      "z": 2,
      "name": "Rock_Slate",
      "rotation": 2
    },
    {
      "x": -2,
      "y": 4,
      "z": 2,
      "name": "Furniture_Jungle_Chair",
      "rotation": 3
    },
    {
      "x": -2,
      "y": 5,
      "z": 2,
      "name": "Furniture_Jungle_Chair",
      "filler": 1024,
      "rotation": 3
    },
    {
      "x": -2,
      "y": 7,
      "z": 2,
      "name": "Rock_Slate",
      "rotation": 2
    },
    {
      "x": -2,
      "y": 8,
      "z": 2,
      "name": "Rock_Slate",
      "rotation": 2
    },
    {
      "x": -2,
      "y": 9,
      "z": 2,
      "name": "Rock_Slate_Brick_Smooth_Half"
    },
    {
      "x": -2,
      "y": 10,
      "z": 2,
      "name": "Prototype_Rock_Concrete_Brick_Roof_Flat",
      "rotation": 1
    },
    {
      "x": -2,
      "y": 2,
      "z": 3,
      "name": "Rock_Slate",
      "rotation": 2
    },
    {
      "x": -2,
      "y": 3,
      "z": 3,
      "name": "Rock_Slate_Brick_Smooth"
    },
    {
      "x": -2,
      "y": 4,
      "z": 3,
      "name": "Furniture_Jungle_Chair",
      "rotation": 3
    },
    {
      "x": -2,
      "y": 5,
      "z": 3,
      "name": "Furniture_Jungle_Chair",
      "filler": 1024,
      "rotation": 3
    },
    {
      "x": -2,
      "y": 7,
      "z": 3,
      "name": "Rock_Slate",
      "rotation": 2
    },
    {
      "x": -2,
      "y": 8,
      "z": 3,
      "name": "Rock_Slate",
      "rotation": 2
    },
    {
      "x": -2,
      "y": 9,
      "z": 3,
      "name": "Rock_Slate_Brick_Smooth_Half"
    },
    {
      "x": -2,
      "y": 10,
      "z": 3,
      "name": "Prototype_Rock_Concrete_Brick_Roof_Flat",
      "rotation": 1
    },
    {
      "x": -2,
      "y": 2,
      "z": 4,
      "name": "Rock_Slate",
      "rotation": 2
    },
    {
      "x": -2,
      "y": 3,
      "z": 4,
      "name": "Rock_Slate_Brick_Smooth"
    },
    {
      "x": -2,
      "y": 4,
      "z": 4,
      "name": "Furniture_Jungle_Chair",
      "rotation": 3
    },
    {
      "x": -2,
      "y": 5,
      "z": 4,
      "name": "Furniture_Jungle_Chair",
      "filler": 1024,
      "rotation": 3
    },
    {
      "x": -2,
      "y": 7,
      "z": 4,
      "name": "Rock_Slate",
      "rotation": 2
    },
    {
      "x": -2,
      "y": 8,
      "z": 4,
      "name": "Rock_Slate",
      "rotation": 2
    },
    {
      "x": -2,
      "y": 10,
      "z": 4,
      "name": "Prototype_Rock_Concrete_Brick_Roof_Flat",
      "rotation": 1
    },
    {
      "x": -2,
      "y": 2,
      "z": 5,
      "name": "Rock_Slate",
      "rotation": 2
    },
    {
      "x": -2,
      "y": 3,
      "z": 5,
      "name": "Rock_Slate",
      "rotation": 2
    },
    {
      "x": -2,
      "y": 4,
      "z": 5,
      "name": "Furniture_Jungle_Chair",
      "rotation": 3
    },
    {
      "x": -2,
      "y": 5,
      "z": 5,
      "name": "Furniture_Jungle_Chair",
      "filler": 1024,
      "rotation": 3
    },
    {
      "x": -2,
      "y": 7,
      "z": 5,
      "name": "Rock_Slate",
      "rotation": 2
    },
    {
      "x": -2,
      "y": 8,
      "z": 5,
      "name": "Rock_Slate",
      "rotation": 2
    },
    {
      "x": -2,
      "y": 10,
      "z": 5,
      "name": "Prototype_Rock_Concrete_Brick_Roof_Flat",
      "rotation": 1
    },
    {
      "x": -2,
      "y": 2,
      "z": 6,
      "name": "Rock_Slate",
      "rotation": 2
    },
    {
      "x": -2,
      "y": 3,
      "z": 6,
      "name": "Rock_Slate",
      "rotation": 2
    },
    {
      "x": -2,
      "y": 4,
      "z": 6,
      "name": "Build_Black_Roof",
      "rotation": 2
    },
    {
      "x": -2,
      "y": 5,
      "z": 6,
      "name": "Build_Black_Roof_Steep",
      "filler": 31744,
      "rotation": 34
    },
    {
      "x": -2,
      "y": 6,
      "z": 6,
      "name": "Build_Black_Roof_Steep",
      "rotation": 34
    },
    {
      "x": -2,
      "y": 7,
      "z": 6,
      "name": "Rock_Slate",
      "rotation": 2
    },
    {
      "x": -2,
      "y": 8,
      "z": 6,
      "name": "Rock_Slate_Brick_Smooth_Half"
    },
    {
      "x": -2,
      "y": 10,
      "z": 6,
      "name": "Prototype_Rock_Concrete_Brick_Roof_Flat",
      "rotation": 1
    },
    {
      "x": -2,
      "y": 2,
      "z": 7,
      "name": "Rock_Slate_Brick_Half",
      "rotation": 4
    },
    {
      "x": -2,
      "y": 3,
      "z": 7,
      "name": "Rock_Slate",
      "rotation": 2
    },
    {
      "x": -2,
      "y": 4,
      "z": 7,
      "name": "Rock_Slate"
    },
    {
      "x": -2,
      "y": 5,
      "z": 7,
      "name": "Rock_Slate"
    },
    {
      "x": -2,
      "y": 6,
      "z": 7,
      "name": "Rock_Slate",
      "rotation": 2
    },
    {
      "x": -2,
      "y": 7,
      "z": 7,
      "name": "Rock_Slate_Brick_Half",
      "rotation": 4
    },
    {
      "x": -2,
      "y": 3,
      "z": 8,
      "name": "Rock_Slate_Brick_Smooth_Half",
      "rotation": 4
    },
    {
      "x": -1,
      "y": 3,
      "z": -1,
      "name": "Rock_Slate_Brick_Smooth_Half",
      "rotation": 6
    },
    {
      "x": -1,
      "y": 4,
      "z": -1,
      "name": "Rock_Slate_Brick_Smooth_Half",
      "rotation": 6
    },
    {
      "x": -1,
      "y": 2,
      "z": 0,
      "name": "Rock_Slate_Brick_Half",
      "rotation": 6
    },
    {
      "x": -1,
      "y": 3,
      "z": 0,
      "name": "Rock_Slate",
      "rotation": 2
    },
    {
      "x": -1,
      "y": 4,
      "z": 0,
      "name": "Rock_Slate"
    },
    {
      "x": -1,
      "y": 5,
      "z": 0,
      "name": "Rock_Slate"
    },
    {
      "x": -1,
      "y": 6,
      "z": 0,
      "name": "Rock_Slate",
      "rotation": 2
    },
    {
      "x": -1,
      "y": 7,
      "z": 0,
      "name": "Rock_Slate_Brick_Half",
      "rotation": 6
    },
    {
      "x": -1,
      "y": 2,
      "z": 1,
      "name": "Rock_Slate",
      "rotation": 2
    },
    {
      "x": -1,
      "y": 3,
      "z": 1,
      "name": "Rock_Slate",
      "rotation": 2
    },
    {
      "x": -1,
      "y": 4,
      "z": 1,
      "name": "Rock_Slate_Brick_Smooth"
    },
    {
      "x": -1,
      "y": 5,
      "z": 1,
      "name": "Rock_Slate_Brick_Smooth"
    },
    {
      "x": -1,
      "y": 6,
      "z": 1,
      "name": "Rock_Slate"
    },
    {
      "x": -1,
      "y": 7,
      "z": 1,
      "name": "Rock_Slate",
      "rotation": 2
    },
    {
      "x": -1,
      "y": 8,
      "z": 1,
      "name": "Rock_Slate_Brick_Smooth_Half"
    },
    {
      "x": -1,
      "y": 10,
      "z": 1,
      "name": "Prototype_Rock_Concrete_Brick_Roof_Flat",
      "rotation": 1
    },
    {
      "x": -1,
      "y": 2,
      "z": 2,
      "name": "Rock_Slate",
      "rotation": 2
    },
    {
      "x": -1,
      "y": 3,
      "z": 2,
      "name": "Rock_Slate",
      "rotation": 2
    },
    {
      "x": -1,
      "y": 4,
      "z": 2,
      "name": "Build_Black_Roof_Steep"
    },
    {
      "x": -1,
      "y": 5,
      "z": 2,
      "name": "Build_Black_Roof_Steep",
      "filler": 1024
    },
    {
      "x": -1,
      "y": 6,
      "z": 2,
      "name": "Rock_Slate_Brick_Smooth"
    },
    {
      "x": -1,
      "y": 7,
      "z": 2,
      "name": "Rock_Slate",
      "rotation": 2
    },
    {
      "x": -1,
      "y": 8,
      "z": 2,
      "name": "Rock_Slate",
      "rotation": 2
    },
    {
      "x": -1,
      "y": 9,
      "z": 2,
      "name": "Rock_Slate_Brick_Half"
    },
    {
      "x": -1,
      "y": 10,
      "z": 2,
      "name": "Prototype_Rock_Concrete_Brick_Roof_Flat",
      "rotation": 1
    },
    {
      "x": -1,
      "y": 2,
      "z": 3,
      "name": "Rock_Slate",
      "rotation": 2
    },
    {
      "x": -1,
      "y": 3,
      "z": 3,
      "name": "Rock_Slate",
      "rotation": 2
    },
    {
      "x": -1,
      "y": 4,
      "z": 3,
      "name": "Build_Black_Roof_Steep",
      "rotation": 2
    },
    {
      "x": -1,
      "y": 5,
      "z": 3,
      "name": "Build_Black_Roof_Steep",
      "filler": 1024,
      "rotation": 2
    },
    {
      "x": -1,
      "y": 6,
      "z": 3,
      "name": "Rock_Slate_Brick_Smooth"
    },
    {
      "x": -1,
      "y": 7,
      "z": 3,
      "name": "Rock_Slate",
      "rotation": 2
    },
    {
      "x": -1,
      "y": 8,
      "z": 3,
      "name": "Rock_Slate_Brick_Smooth"
    },
    {
      "x": -1,
      "y": 9,
      "z": 3,
      "name": "Rock_Slate_Brick_Half"
    },
    {
      "x": -1,
      "y": 2,
      "z": 4,
      "name": "Rock_Slate",
      "rotation": 2
    },
    {
      "x": -1,
      "y": 3,
      "z": 4,
      "name": "Rock_Slate",
      "rotation": 2
    },
    {
      "x": -1,
      "y": 4,
      "z": 4,
      "name": "Build_Black_Roof_Steep"
    },
    {
      "x": -1,
      "y": 5,
      "z": 4,
      "name": "Build_Black_Roof_Steep",
      "filler": 1024
    },
    {
      "x": -1,
      "y": 6,
      "z": 4,
      "name": "Rock_Slate_Brick_Smooth"
    },
    {
      "x": -1,
      "y": 7,
      "z": 4,
      "name": "Rock_Slate",
      "rotation": 2
    },
    {
      "x": -1,
      "y": 8,
      "z": 4,
      "name": "Rock_Slate_Brick_Smooth"
    },
    {
      "x": -1,
      "y": 2,
      "z": 5,
      "name": "Rock_Slate",
      "rotation": 2
    },
    {
      "x": -1,
      "y": 3,
      "z": 5,
      "name": "Rock_Slate",
      "rotation": 2
    },
    {
      "x": -1,
      "y": 4,
      "z": 5,
      "name": "Build_Black_Roof_Steep",
      "rotation": 2
    },
    {
      "x": -1,
      "y": 5,
      "z": 5,
      "name": "Build_Black_Roof_Steep",
      "filler": 1024,
      "rotation": 2
    },
    {
      "x": -1,
      "y": 6,
      "z": 5,
      "name": "Rock_Slate_Brick_Smooth"
    },
    {
      "x": -1,
      "y": 7,
      "z": 5,
      "name": "Rock_Slate",
      "rotation": 2
    },
    {
      "x": -1,
      "y": 8,
      "z": 5,
      "name": "Rock_Slate",
      "rotation": 2
    },
    {
      "x": -1,
      "y": 10,
      "z": 5,
      "name": "Prototype_Rock_Concrete_Brick_Roof_Flat",
      "rotation": 1
    },
    {
      "x": -1,
      "y": 2,
      "z": 6,
      "name": "Rock_Slate",
      "rotation": 2
    },
    {
      "x": -1,
      "y": 3,
      "z": 6,
      "name": "Rock_Slate",
      "rotation": 2
    },
    {
      "x": -1,
      "y": 4,
      "z": 6,
      "name": "Rock_Slate_Brick_Smooth"
    },
    {
      "x": -1,
      "y": 5,
      "z": 6,
      "name": "Rock_Slate_Brick_Smooth"
    },
    {
      "x": -1,
      "y": 6,
      "z": 6,
      "name": "Rock_Slate"
    },
    {
      "x": -1,
      "y": 7,
      "z": 6,
      "name": "Rock_Slate",
      "rotation": 2
    },
    {
      "x": -1,
      "y": 8,
      "z": 6,
      "name": "Rock_Slate_Brick_Smooth_Half"
    },
    {
      "x": -1,
      "y": 10,
      "z": 6,
      "name": "Prototype_Rock_Concrete_Brick_Roof_Flat",
      "rotation": 1
    },
    {
      "x": -1,
      "y": 2,
      "z": 7,
      "name": "Rock_Slate_Brick_Half",
      "rotation": 4
    },
    {
      "x": -1,
      "y": 3,
      "z": 7,
      "name": "Rock_Slate",
      "rotation": 2
    },
    {
      "x": -1,
      "y": 4,
      "z": 7,
      "name": "Rock_Slate",
      "rotation": 2
    },
    {
      "x": -1,
      "y": 5,
      "z": 7,
      "name": "Rock_Slate",
      "rotation": 2
    },
    {
      "x": -1,
      "y": 6,
      "z": 7,
      "name": "Rock_Slate",
      "rotation": 2
    },
    {
      "x": -1,
      "y": 7,
      "z": 7,
      "name": "Rock_Slate_Brick_Half",
      "rotation": 4
    },
    {
      "x": -1,
      "y": 10,
      "z": 7,
      "name": "Prototype_Rock_Concrete_Brick_Roof_Flat",
      "rotation": 1
    },
    {
      "x": -1,
      "y": 3,
      "z": 8,
      "name": "Rock_Slate_Brick_Smooth_Half",
      "rotation": 4
    },
    {
      "x": -1,
      "y": 4,
      "z": 8,
      "name": "Rock_Slate_Brick_Smooth_Half",
      "rotation": 4
    },
    {
      "x": 0,
      "y": 3,
      "z": -1,
      "name": "Rock_Slate_Brick_Smooth_Half",
      "rotation": 6
    },
    {
      "x": 0,
      "y": 4,
      "z": -1,
      "name": "Rock_Slate_Brick_Smooth_Half",
      "rotation": 6
    },
    {
      "x": 0,
      "y": 7,
      "z": -1,
      "name": "Rock_Slate_Brick_Smooth_Half",
      "rotation": 6
    },
    {
      "x": 0,
      "y": 2,
      "z": 0,
      "name": "Rock_Slate_Brick_Half",
      "rotation": 6
    },
    {
      "x": 0,
      "y": 3,
      "z": 0,
      "name": "Rock_Slate",
      "rotation": 2
    },
    {
      "x": 0,
      "y": 4,
      "z": 0,
      "name": "Rock_Slate",
      "rotation": 2
    },
    {
      "x": 0,
      "y": 5,
      "z": 0,
      "name": "Rock_Slate",
      "rotation": 2
    },
    {
      "x": 0,
      "y": 6,
      "z": 0,
      "name": "Rock_Slate",
      "rotation": 2
    },
    {
      "x": 0,
      "y": 7,
      "z": 0,
      "name": "Rock_Slate_Brick_Smooth"
    },
    {
      "x": 0,
      "y": 10,
      "z": 0,
      "name": "Prototype_Rock_Concrete_Brick_Roof_Flat",
      "rotation": 1
    },
    {
      "x": 0,
      "y": 2,
      "z": 1,
      "name": "Rock_Slate",
      "rotation": 2
    },
    {
      "x": 0,
      "y": 3,
      "z": 1,
      "name": "Rock_Slate",
      "rotation": 2
    },
    {
      "x": 0,
      "y": 4,
      "z": 1,
      "name": "Rock_Slate"
    },
    {
      "x": 0,
      "y": 5,
      "z": 1,
      "name": "Rock_Slate"
    },
    {
      "x": 0,
      "y": 6,
      "z": 1,
      "name": "Ore_Cobalt_Slate"
    },
    {
      "x": 0,
      "y": 7,
      "z": 1,
      "name": "Rock_Slate",
      "rotation": 2
    },
    {
      "x": 0,
      "y": 10,
      "z": 1,
      "name": "Prototype_Rock_Concrete_Brick_Roof_Flat",
      "rotation": 1
    },
    {
      "x": 0,
      "y": 2,
      "z": 2,
      "name": "Rock_Slate",
      "rotation": 2
    },
    {
      "x": 0,
      "y": 3,
      "z": 2,
      "name": "Rock_Slate",
      "rotation": 2
    },
    {
      "x": 0,
      "y": 4,
      "z": 2,
      "name": "Rock_Slate"
    },
    {
      "x": 0,
      "y": 5,
      "z": 2,
      "name": "Rock_Slate"
    },
    {
      "x": 0,
      "y": 6,
      "z": 2,
      "name": "Rock_Slate"
    },
    {
      "x": 0,
      "y": 7,
      "z": 2,
      "name": "Rock_Slate",
      "rotation": 2
    },
    {
      "x": 0,
      "y": 8,
      "z": 2,
      "name": "Rock_Slate",
      "rotation": 2
    },
    {
      "x": 0,
      "y": 9,
      "z": 2,
      "name": "Rock_Slate_Brick_Roof_Flat"
    },
    {
      "x": 0,
      "y": 10,
      "z": 2,
      "name": "Prototype_Rock_Concrete_Brick_Roof_Flat",
      "rotation": 1
    },
    {
      "x": 0,
      "y": 1,
      "z": 3,
      "name": "Rock_Slate_Brick_Roof_Flat",
      "rotation": 35
    },
    {
      "x": 0,
      "y": 2,
      "z": 3,
      "name": "Rock_Slate",
      "rotation": 2
    },
    {
      "x": 0,
      "y": 3,
      "z": 3,
      "name": "Rock_Slate",
      "rotation": 2
    },
    {
      "x": 0,
      "y": 4,
      "z": 3,
      "name": "Rock_Slate"
    },
    {
      "x": 0,
      "y": 5,
      "z": 3,
      "name": "Rock_Slate"
    },
    {
      "x": 0,
      "y": 6,
      "z": 3,
      "name": "Rock_Slate"
    },
    {
      "x": 0,
      "y": 7,
      "z": 3,
      "name": "Rock_Slate",
      "rotation": 2
    },
    {
      "x": 0,
      "y": 8,
      "z": 3,
      "name": "Rock_Slate_Brick_Smooth"
    },
    {
      "x": 0,
      "y": 9,
      "z": 3,
      "name": "Rock_Slate_Brick_Roof_Flat"
    },
    {
      "x": 0,
      "y": 1,
      "z": 4,
      "name": "Rock_Slate_Brick_Roof_Flat",
      "rotation": 35
    },
    {
      "x": 0,
      "y": 2,
      "z": 4,
      "name": "Rock_Slate",
      "rotation": 2
    },
    {
      "x": 0,
      "y": 3,
      "z": 4,
      "name": "Rock_Slate",
      "rotation": 2
    },
    {
      "x": 0,
      "y": 4,
      "z": 4,
      "name": "Rock_Slate"
    },
    {
      "x": 0,
      "y": 5,
      "z": 4,
      "name": "Rock_Slate"
    },
    {
      "x": 0,
      "y": 6,
      "z": 4,
      "name": "Rock_Slate"
    },
    {
      "x": 0,
      "y": 7,
      "z": 4,
      "name": "Rock_Slate",
      "rotation": 2
    },
    {
      "x": 0,
      "y": 8,
      "z": 4,
      "name": "Rock_Slate_Brick_Smooth"
    },
    {
      "x": 0,
      "y": 2,
      "z": 5,
      "name": "Rock_Slate",
      "rotation": 2
    },
    {
      "x": 0,
      "y": 3,
      "z": 5,
      "name": "Rock_Slate",
      "rotation": 2
    },
    {
      "x": 0,
      "y": 4,
      "z": 5,
      "name": "Rock_Slate"
    },
    {
      "x": 0,
      "y": 5,
      "z": 5,
      "name": "Rock_Slate"
    },
    {
      "x": 0,
      "y": 6,
      "z": 5,
      "name": "Rock_Slate"
    },
    {
      "x": 0,
      "y": 7,
      "z": 5,
      "name": "Rock_Slate",
      "rotation": 2
    },
    {
      "x": 0,
      "y": 8,
      "z": 5,
      "name": "Rock_Slate",
      "rotation": 2
    },
    {
      "x": 0,
      "y": 2,
      "z": 6,
      "name": "Rock_Slate",
      "rotation": 2
    },
    {
      "x": 0,
      "y": 3,
      "z": 6,
      "name": "Rock_Slate",
      "rotation": 2
    },
    {
      "x": 0,
      "y": 4,
      "z": 6,
      "name": "Rock_Slate"
    },
    {
      "x": 0,
      "y": 5,
      "z": 6,
      "name": "Rock_Slate"
    },
    {
      "x": 0,
      "y": 6,
      "z": 6,
      "name": "Ore_Cobalt_Slate"
    },
    {
      "x": 0,
      "y": 7,
      "z": 6,
      "name": "Rock_Slate",
      "rotation": 2
    },
    {
      "x": 0,
      "y": 10,
      "z": 6,
      "name": "Prototype_Rock_Concrete_Brick_Roof_Flat",
      "rotation": 1
    },
    {
      "x": 0,
      "y": 2,
      "z": 7,
      "name": "Rock_Slate_Brick_Half",
      "rotation": 4
    },
    {
      "x": 0,
      "y": 3,
      "z": 7,
      "name": "Rock_Slate",
      "rotation": 2
    },
    {
      "x": 0,
      "y": 4,
      "z": 7,
      "name": "Rock_Slate",
      "rotation": 2
    },
    {
      "x": 0,
      "y": 5,
      "z": 7,
      "name": "Rock_Slate",
      "rotation": 2
    },
    {
      "x": 0,
      "y": 6,
      "z": 7,
      "name": "Rock_Slate",
      "rotation": 2
    },
    {
      "x": 0,
      "y": 7,
      "z": 7,
      "name": "Rock_Slate_Brick_Smooth"
    },
    {
      "x": 0,
      "y": 10,
      "z": 7,
      "name": "Prototype_Rock_Concrete_Brick_Roof_Flat",
      "rotation": 1
    },
    {
      "x": 0,
      "y": 3,
      "z": 8,
      "name": "Rock_Slate_Brick_Smooth_Half",
      "rotation": 4
    },
    {
      "x": 0,
      "y": 4,
      "z": 8,
      "name": "Rock_Slate_Brick_Smooth_Half",
      "rotation": 4
    },
    {
      "x": 0,
      "y": 10,
      "z": 8,
      "name": "Prototype_Rock_Concrete_Brick_Roof_Flat",
      "rotation": 1
    },
    {
      "x": 1,
      "y": 7,
      "z": -1,
      "name": "Rock_Slate_Brick_Smooth_Half",
      "rotation": 6
    },
    {
      "x": 1,
      "y": 3,
      "z": 0,
      "name": "Rock_Slate_Brick_Half",
      "rotation": 6
    },
    {
      "x": 1,
      "y": 4,
      "z": 0,
      "name": "Rock_Slate_Brick_Half",
      "rotation": 6
    },
    {
      "x": 1,
      "y": 5,
      "z": 0,
      "name": "Rock_Slate_Brick_Half",
      "rotation": 6
    },
    {
      "x": 1,
      "y": 6,
      "z": 0,
      "name": "Rock_Slate_Brick_Smooth"
    },
    {
      "x": 1,
      "y": 7,
      "z": 0,
      "name": "Rock_Slate_Brick_Smooth"
    },
    {
      "x": 1,
      "y": 10,
      "z": 0,
      "name": "Prototype_Rock_Concrete_Brick_Roof_Flat",
      "rotation": 1
    },
    {
      "x": 1,
      "y": 2,
      "z": 1,
      "name": "Rock_Slate",
      "rotation": 2
    },
    {
      "x": 1,
      "y": 3,
      "z": 1,
      "name": "Rock_Slate",
      "rotation": 2
    },
    {
      "x": 1,
      "y": 4,
      "z": 1,
      "name": "Rock_Slate"
    },
    {
      "x": 1,
      "y": 5,
      "z": 1,
      "name": "Rock_Slate"
    },
    {
      "x": 1,
      "y": 7,
      "z": 1,
      "name": "Rock_Slate",
      "rotation": 2
    },
    {
      "x": 1,
      "y": 10,
      "z": 1,
      "name": "Prototype_Rock_Concrete_Brick_Roof_Flat",
      "rotation": 1
    },
    {
      "x": 1,
      "y": 2,
      "z": 2,
      "name": "Rock_Slate",
      "rotation": 2
    },
    {
      "x": 1,
      "y": 3,
      "z": 2,
      "name": "Rock_Slate",
      "rotation": 2
    },
    {
      "x": 1,
      "y": 4,
      "z": 2,
      "name": "Rock_Slate"
    },
    {
      "x": 1,
      "y": 5,
      "z": 2,
      "name": "Rock_Slate"
    },
    {
      "x": 1,
      "y": 6,
      "z": 2,
      "name": "Rock_Slate",
      "rotation": 2
    },
    {
      "x": 1,
      "y": 7,
      "z": 2,
      "name": "Rock_Slate",
      "rotation": 2
    },
    {
      "x": 1,
      "y": 8,
      "z": 2,
      "name": "Build_Black_Roof",
      "rotation": 1
    },
    {
      "x": 1,
      "y": 1,
      "z": 3,
      "name": "Rock_Slate_Brick_Roof_Flat",
      "rotation": 34
    },
    {
      "x": 1,
      "y": 2,
      "z": 3,
      "name": "Rock_Slate",
      "rotation": 2
    },
    {
      "x": 1,
      "y": 3,
      "z": 3,
      "name": "Rock_Slate",
      "rotation": 2
    },
    {
      "x": 1,
      "y": 6,
      "z": 3,
      "name": "Rock_Slate",
      "rotation": 2
    },
    {
      "x": 1,
      "y": 7,
      "z": 3,
      "name": "Rock_Slate",
      "rotation": 2
    },
    {
      "x": 1,
      "y": 8,
      "z": 3,
      "name": "Rock_Slate_Brick_Smooth"
    },
    {
      "x": 1,
      "y": 1,
      "z": 4,
      "name": "Rock_Slate_Brick_Roof_Flat",
      "rotation": 35
    },
    {
      "x": 1,
      "y": 2,
      "z": 4,
      "name": "Rock_Slate",
      "rotation": 2
    },
    {
      "x": 1,
      "y": 3,
      "z": 4,
      "name": "Rock_Slate",
      "rotation": 2
    },
    {
      "x": 1,
      "y": 6,
      "z": 4,
      "name": "Rock_Slate",
      "rotation": 2
    },
    {
      "x": 1,
      "y": 7,
      "z": 4,
      "name": "Rock_Slate",
      "rotation": 2
    },
    {
      "x": 1,
      "y": 8,
      "z": 4,
      "name": "Rock_Slate_Brick_Smooth"
    },
    {
      "x": 1,
      "y": 2,
      "z": 5,
      "name": "Rock_Slate",
      "rotation": 2
    },
    {
      "x": 1,
      "y": 3,
      "z": 5,
      "name": "Rock_Slate",
      "rotation": 2
    },
    {
      "x": 1,
      "y": 4,
      "z": 5,
      "name": "Rock_Slate"
    },
    {
      "x": 1,
      "y": 5,
      "z": 5,
      "name": "Rock_Slate"
    },
    {
      "x": 1,
      "y": 6,
      "z": 5,
      "name": "Rock_Slate",
      "rotation": 2
    },
    {
      "x": 1,
      "y": 7,
      "z": 5,
      "name": "Rock_Slate",
      "rotation": 2
    },
    {
      "x": 1,
      "y": 8,
      "z": 5,
      "name": "Build_Black_Roof",
      "rotation": 1
    },
    {
      "x": 1,
      "y": 2,
      "z": 6,
      "name": "Rock_Slate",
      "rotation": 2
    },
    {
      "x": 1,
      "y": 3,
      "z": 6,
      "name": "Rock_Slate",
      "rotation": 2
    },
    {
      "x": 1,
      "y": 4,
      "z": 6,
      "name": "Rock_Slate",
      "rotation": 2
    },
    {
      "x": 1,
      "y": 5,
      "z": 6,
      "name": "Rock_Slate"
    },
    {
      "x": 1,
      "y": 7,
      "z": 6,
      "name": "Rock_Slate",
      "rotation": 2
    },
    {
      "x": 1,
      "y": 3,
      "z": 7,
      "name": "Rock_Slate_Brick_Half",
      "rotation": 4
    },
    {
      "x": 1,
      "y": 4,
      "z": 7,
      "name": "Rock_Slate_Brick_Half",
      "rotation": 4
    },
    {
      "x": 1,
      "y": 5,
      "z": 7,
      "name": "Rock_Slate"
    },
    {
      "x": 1,
      "y": 6,
      "z": 7,
      "name": "Rock_Slate_Brick_Smooth"
    },
    {
      "x": 1,
      "y": 7,
      "z": 7,
      "name": "Rock_Slate_Brick_Smooth"
    },
    {
      "x": 1,
      "y": 10,
      "z": 7,
      "name": "Prototype_Rock_Concrete_Brick_Roof_Flat",
      "rotation": 2
    },
    {
      "x": 1,
      "y": 10,
      "z": 8,
      "name": "Prototype_Rock_Concrete_Brick_Roof_Flat",
      "rotation": 1
    },
    {
      "x": 1,
      "y": 10,
      "z": 9,
      "name": "Prototype_Rock_Concrete_Brick_Roof_Flat",
      "rotation": 1
    },
    {
      "x": 2,
      "y": 10,
      "z": -1,
      "name": "Prototype_Rock_Concrete_Brick_Roof_Flat",
      "rotation": 1
    },
    {
      "x": 2,
      "y": 3,
      "z": 0,
      "name": "Rock_Slate_Brick_Half",
      "rotation": 6
    },
    {
      "x": 2,
      "y": 5,
      "z": 0,
      "name": "Rock_Slate_Brick_Smooth_Half",
      "rotation": 6
    },
    {
      "x": 2,
      "y": 6,
      "z": 0,
      "name": "Rock_Slate_Brick_Smooth_Half",
      "rotation": 6
    },
    {
      "x": 2,
      "y": 7,
      "z": 0,
      "name": "Rock_Slate_Brick_Smooth_Half",
      "rotation": 6
    },
    {
      "x": 2,
      "y": 10,
      "z": 0,
      "name": "Prototype_Rock_Concrete_Brick_Roof_Flat",
      "rotation": 1
    },
    {
      "x": 2,
      "y": 2,
      "z": 1,
      "name": "Rock_Slate_Brick_Half",
      "rotation": 34
    },
    {
      "x": 2,
      "y": 3,
      "z": 1,
      "name": "Rock_Slate",
      "rotation": 2
    },
    {
      "x": 2,
      "y": 4,
      "z": 1,
      "name": "Rock_Slate",
      "rotation": 2
    },
    {
      "x": 2,
      "y": 5,
      "z": 1,
      "name": "Rock_Slate",
      "rotation": 2
    },
    {
      "x": 2,
      "y": 6,
      "z": 1,
      "name": "Rock_Slate_Brick_Half"
    },
    {
      "x": 2,
      "y": 7,
      "z": 1,
      "name": "Build_Black_Roof_Shallow",
      "filler": 31,
      "rotation": 33
    },
    {
      "x": 2,
      "y": 10,
      "z": 1,
      "name": "Prototype_Rock_Concrete_Brick_Roof_Flat",
      "rotation": 1
    },
    {
      "x": 2,
      "y": 2,
      "z": 2,
      "name": "Rock_Slate",
      "rotation": 2
    },
    {
      "x": 2,
      "y": 3,
      "z": 2,
      "name": "Rock_Slate",
      "rotation": 2
    },
    {
      "x": 2,
      "y": 4,
      "z": 2,
      "name": "Rock_Slate"
    },
    {
      "x": 2,
      "y": 5,
      "z": 2,
      "name": "Rock_Slate"
    },
    {
      "x": 2,
      "y": 6,
      "z": 2,
      "name": "Rock_Slate",
      "rotation": 2
    },
    {
      "x": 2,
      "y": 7,
      "z": 2,
      "name": "Rock_Slate",
      "rotation": 2
    },
    {
      "x": 2,
      "y": 1,
      "z": 3,
      "name": "Rock_Slate_Brick_Roof_Flat",
      "rotation": 35
    },
    {
      "x": 2,
      "y": 2,
      "z": 3,
      "name": "Rock_Slate",
      "rotation": 2
    },
    {
      "x": 2,
      "y": 3,
      "z": 3,
      "name": "Rock_Slate",
      "rotation": 2
    },
    {
      "x": 2,
      "y": 4,
      "z": 3,
      "name": "T_SWAYLF",
      "rotation": 3
    },
    {
      "x": 2,
      "y": 6,
      "z": 3,
      "name": "Rock_Slate",
      "rotation": 2
    },
    {
      "x": 2,
      "y": 7,
      "z": 3,
      "name": "Rock_Slate",
      "rotation": 2
    },
    {
      "x": 2,
      "y": 8,
      "z": 3,
      "name": "Build_Black_Roof",
      "rotation": 1
    },
    {
      "x": 2,
      "y": 1,
      "z": 4,
      "name": "Rock_Slate_Brick_Roof_Flat",
      "rotation": 35
    },
    {
      "x": 2,
      "y": 2,
      "z": 4,
      "name": "Rock_Slate",
      "rotation": 2
    },
    {
      "x": 2,
      "y": 3,
      "z": 4,
      "name": "Rock_Slate",
      "rotation": 2
    },
    {
      "x": 2,
      "y": 6,
      "z": 4,
      "name": "Rock_Slate",
      "rotation": 2
    },
    {
      "x": 2,
      "y": 7,
      "z": 4,
      "name": "Rock_Slate",
      "rotation": 2
    },
    {
      "x": 2,
      "y": 8,
      "z": 4,
      "name": "Build_Black_Roof",
      "rotation": 1
    },
    {
      "x": 2,
      "y": 2,
      "z": 5,
      "name": "Rock_Slate",
      "rotation": 2
    },
    {
      "x": 2,
      "y": 3,
      "z": 5,
      "name": "Rock_Slate",
      "rotation": 2
    },
    {
      "x": 2,
      "y": 4,
      "z": 5,
      "name": "Rock_Slate"
    },
    {
      "x": 2,
      "y": 5,
      "z": 5,
      "name": "Rock_Slate"
    },
    {
      "x": 2,
      "y": 6,
      "z": 5,
      "name": "Rock_Slate",
      "rotation": 2
    },
    {
      "x": 2,
      "y": 7,
      "z": 5,
      "name": "Rock_Slate",
      "rotation": 2
    },
    {
      "x": 2,
      "y": 2,
      "z": 6,
      "name": "Rock_Slate_Brick_Half",
      "rotation": 34
    },
    {
      "x": 2,
      "y": 3,
      "z": 6,
      "name": "Rock_Slate",
      "rotation": 2
    },
    {
      "x": 2,
      "y": 4,
      "z": 6,
      "name": "Rock_Slate",
      "rotation": 2
    },
    {
      "x": 2,
      "y": 5,
      "z": 6,
      "name": "Rock_Slate",
      "rotation": 2
    },
    {
      "x": 2,
      "y": 6,
      "z": 6,
      "name": "Rock_Slate_Brick_Half"
    },
    {
      "x": 2,
      "y": 7,
      "z": 6,
      "name": "Build_Black_Roof_Shallow",
      "filler": 31,
      "rotation": 33
    },
    {
      "x": 2,
      "y": 3,
      "z": 7,
      "name": "Rock_Slate_Brick_Half",
      "rotation": 4
    },
    {
      "x": 2,
      "y": 5,
      "z": 7,
      "name": "Rock_Slate_Brick_Smooth_Half",
      "rotation": 4
    },
    {
      "x": 2,
      "y": 6,
      "z": 7,
      "name": "Rock_Slate_Brick_Smooth_Half",
      "rotation": 4
    },
    {
      "x": 2,
      "y": 7,
      "z": 7,
      "name": "Rock_Slate_Brick_Smooth_Half",
      "rotation": 4
    },
    {
      "x": 2,
      "y": 10,
      "z": 8,
      "name": "Prototype_Rock_Concrete_Brick_Roof_Flat",
      "rotation": 2
    },
    {
      "x": 2,
      "y": 10,
      "z": 9,
      "name": "Prototype_Rock_Concrete_Brick_Roof_Flat",
      "rotation": 1
    },
    {
      "x": 2,
      "y": 10,
      "z": 10,
      "name": "Prototype_Rock_Concrete_Brick_Roof_Flat",
      "rotation": 1
    },
    {
      "x": 3,
      "y": 10,
      "z": -1,
      "name": "Prototype_Rock_Concrete_Brick_Roof_Flat",
      "rotation": 1
    },
    {
      "x": 3,
      "y": 6,
      "z": 0,
      "name": "Rock_Slate_Brick_Half",
      "rotation": 6
    },
    {
      "x": 3,
      "y": 7,
      "z": 0,
      "name": "Rock_Slate_Brick_Half",
      "rotation": 6
    },
    {
      "x": 3,
      "y": 10,
      "z": 0,
      "name": "Prototype_Rock_Concrete_Brick_Roof_Flat",
      "rotation": 1
    },
    {
      "x": 3,
      "y": 3,
      "z": 1,
      "name": "Rock_Slate_Brick_Half",
      "rotation": 34
    },
    {
      "x": 3,
      "y": 4,
      "z": 1,
      "name": "Rock_Slate",
      "rotation": 2
    },
    {
      "x": 3,
      "y": 5,
      "z": 1,
      "name": "Build_Black_Roof",
      "rotation": 1
    },
    {
      "x": 3,
      "y": 6,
      "z": 1,
      "name": "Rock_Slate_Brick_Half"
    },
    {
      "x": 3,
      "y": 7,
      "z": 1,
      "name": "Build_Black_Roof_Shallow",
      "rotation": 33
    },
    {
      "x": 3,
      "y": 2,
      "z": 2,
      "name": "Rock_Slate",
      "rotation": 2
    },
    {
      "x": 3,
      "y": 3,
      "z": 2,
      "name": "Rock_Slate",
      "rotation": 2
    },
    {
      "x": 3,
      "y": 4,
      "z": 2,
      "name": "Rock_Slate",
      "rotation": 2
    },
    {
      "x": 3,
      "y": 5,
      "z": 2,
      "name": "Rock_Slate",
      "rotation": 2
    },
    {
      "x": 3,
      "y": 6,
      "z": 2,
      "name": "Rock_Slate",
      "rotation": 2
    },
    {
      "x": 3,
      "y": 7,
      "z": 2,
      "name": "Rock_Slate",
      "rotation": 2
    },
    {
      "x": 3,
      "y": 1,
      "z": 3,
      "name": "Rock_Slate_Brick_Roof_Flat",
      "rotation": 35
    },
    {
      "x": 3,
      "y": 2,
      "z": 3,
      "name": "Rock_Slate",
      "rotation": 2
    },
    {
      "x": 3,
      "y": 3,
      "z": 3,
      "name": "Rock_Slate",
      "rotation": 2
    },
    {
      "x": 3,
      "y": 6,
      "z": 3,
      "name": "Rock_Slate_Brick_Smooth"
    },
    {
      "x": 3,
      "y": 7,
      "z": 3,
      "name": "Rock_Slate_Brick_Smooth"
    },
    {
      "x": 3,
      "y": 1,
      "z": 4,
      "name": "Rock_Slate_Brick_Roof_Flat",
      "rotation": 35
    },
    {
      "x": 3,
      "y": 2,
